<?xml version="1.0" encoding="utf-8"?>
<!-- =================================================================================== -->
<!-- |    This document was autogenerated by xacro from /home/ben/catkin_ws/src/Soft-Arm-Main/urdf/output.xacro | -->
<!-- |    EDITING THIS FILE BY HAND IS NOT RECOMMENDED                                 | -->
<!-- =================================================================================== -->
<robot name="Design">
  <!--<xacro:include filename="$(find gripper_description)/urdf/materials.xacro" />-->
  <!--<xacro:include filename="$(find gripper_description)/urdf/Design.gazebo" />-->
  <!-- see https://secure.wikimedia.org/wikipedia/en/wiki/List_of_moment_of_inertia_tensors -->
  <!--<xacro:include filename="$(find version1_description)/urdf/materials.xacro" />
<xacro:include filename="$(find version1_description)/urdf/Design.gazebo" /> -->
  <transmission name="Rev1_tran">
    <type>transmission_interface/SimpleTransmission</type>
    <joint name="Rev1">
      <hardwareInterface>hardware_interface/EffortJointInterface</hardwareInterface>
    </joint>
    <actuator name="Rev1_actr">
      <mechanicalReduction>1</mechanicalReduction>
    </actuator>
  </transmission>
  <transmission name="Rev2_tran">
    <type>transmission_interface/SimpleTransmission</type>
    <joint name="Rev2">
      <hardwareInterface>hardware_interface/EffortJointInterface</hardwareInterface>
    </joint>
    <actuator name="Rev2_actr">
      <mechanicalReduction>1</mechanicalReduction>
    </actuator>
  </transmission>
  <transmission name="Rev3_tran">
    <type>transmission_interface/SimpleTransmission</type>
    <joint name="Rev3">
      <hardwareInterface>hardware_interface/EffortJointInterface</hardwareInterface>
    </joint>
    <actuator name="Rev3_actr">
      <mechanicalReduction>1</mechanicalReduction>
    </actuator>
  </transmission>
  <transmission name="Rev4_tran">
    <type>transmission_interface/SimpleTransmission</type>
    <joint name="Rev4">
      <hardwareInterface>hardware_interface/EffortJointInterface</hardwareInterface>
    </joint>
    <actuator name="Rev4_actr">
      <mechanicalReduction>1</mechanicalReduction>
    </actuator>
  </transmission>
  <!--  PROPERTIES  -->
  <!-- LINKS  -->
  <!--<xacro:include filename="$(find design2_description)/urdf/materials.xacro" />-->
  <!--<xacro:include filename="$(find design2_description)/urdf/design2.trans" />-->
  <!--<xacro:include filename="$(find design2_description)/urdf/design2.gazebo" />-->
  <link name="base_link">
    <inertial>
      <origin rpy="0 0 0" xyz="-6.108345103356556e-15 5.090287586130463e-17 0.01965246769632399"/>
      <mass value="16.83095492294922"/>
      <inertia ixx="0.079936" ixy="0.0" ixz="-0.0" iyy="0.079936" iyz="0.0" izz="0.152021"/>
    </inertial>
    <visual>
      <origin rpy="0 0 0" xyz="0 0 0"/>
      <geometry>
        <mesh filename="package://main_description/meshes/base_link.stl" scale="0.001 0.001 0.001"/>
      </geometry>
      <material name="silver"/>
    </visual>
    <collision>
      <origin rpy="0 0 0" xyz="0 0 0"/>
      <geometry>
        <mesh filename="package://main_description/meshes/base_link.stl" scale="0.001 0.001 0.001"/>
      </geometry>
    </collision>
  </link>
  <link name="Link1_1">
    <inertial>
      <origin rpy="0 0 0" xyz="-1.2279118486616705e-05 0.01442476351451121 0.020602870891923072"/>
      <mass value="0.9178712114753625"/>
      <inertia ixx="0.002553" ixy="0.0" ixz="0.0" iyy="0.002018" iyz="-0.00035" izz="0.00387"/>
    </inertial>
    <visual>
      <origin rpy="0 0 0" xyz="-0.0 -0.0 -0.05"/>
      <geometry>
        <mesh filename="package://main_description/meshes/Link1_1.stl" scale="0.001 0.001 0.001"/>
      </geometry>
      <material name="silver"/>
    </visual>
    <collision>
      <origin rpy="0 0 0" xyz="-0.0 -0.0 -0.05"/>
      <geometry>
        <mesh filename="package://main_description/meshes/Link1_1.stl" scale="0.001 0.001 0.001"/>
      </geometry>
    </collision>
  </link>
  <link name="Link2_1">
    <inertial>
      <origin rpy="0 0 0" xyz="-2.968335648842978e-07 0.018054267252499347 0.1868568711048091"/>
      <mass value="0.712050673323837"/>
      <inertia ixx="0.008737" ixy="0.0" ixz="0.0" iyy="0.008392" iyz="-0.001509" izz="0.000705"/>
    </inertial>
    <visual>
      <origin rpy="0 0 0" xyz="4.2e-05 -0.009807 -0.1"/>
      <geometry>
        <mesh filename="package://main_description/meshes/Link2_1.stl" scale="0.001 0.001 0.001"/>
      </geometry>
      <material name="silver"/>
    </visual>
    <collision>
      <origin rpy="0 0 0" xyz="4.2e-05 -0.009807 -0.1"/>
      <geometry>
        <mesh filename="package://main_description/meshes/Link2_1.stl" scale="0.001 0.001 0.001"/>
      </geometry>
    </collision>
  </link>
  <link name="Link3_1">
    <inertial>
      <origin rpy="0 0 0" xyz="3.894856228585856e-05 0.012744269230917583 0.14887041213898544"/>
      <mass value="0.5352959751924613"/>
      <inertia ixx="0.004471" ixy="-0.0" ixz="-1e-06" iyy="0.004348" iyz="-0.000747" izz="0.000361"/>
    </inertial>
    <visual>
      <origin rpy="0 0 0" xyz="4.2e-05 -0.009807 -0.4"/>
      <geometry>
        <mesh filename="package://main_description/meshes/Link3_1.stl" scale="0.001 0.001 0.001"/>
      </geometry>
      <material name="silver"/>
    </visual>
    <collision>
      <origin rpy="0 0 0" xyz="4.2e-05 -0.009807 -0.4"/>
      <geometry>
        <mesh filename="package://main_description/meshes/Link3_1.stl" scale="0.001 0.001 0.001"/>
      </geometry>
    </collision>
  </link>
  <link name="Link4_1">
    <inertial>
      <origin rpy="0 0 0" xyz="-3.684166078735014e-07 -0.010000499675700233 0.06497387205009375"/>
      <mass value="0.18168902324741887"/>
      <inertia ixx="0.000446" ixy="0.0" ixz="0.0" iyy="0.000477" iyz="0.0" izz="4.3e-05"/>
    </inertial>
    <visual>
      <origin rpy="0 0 0" xyz="-2.4e-05 -0.009807 -0.65"/>
      <geometry>
        <mesh filename="package://main_description/meshes/Link4_1.stl" scale="0.001 0.001 0.001"/>
      </geometry>
      <material name="silver"/>
    </visual>
    <collision>
      <origin rpy="0 0 0" xyz="-2.4e-05 -0.009807 -0.65"/>
      <geometry>
        <mesh filename="package://main_description/meshes/Link4_1.stl" scale="0.001 0.001 0.001"/>
      </geometry>
    </collision>
  </link>
  <!--  JOINTS  -->
  <joint name="world_joint" type="fixed">
    <axis xyz="0 0 1"/>
    <origin rpy="0 0 0" xyz="0.0 0.0 0.0"/>
    <parent link="world"/>
    <child link="base_link"/>
  </joint>
  <joint name="Rev1" type="continuous">
    <origin rpy="0 0 0" xyz="0.0 0.0 0.05"/>
    <parent link="base_link"/>
    <child link="Link1_1"/>
    <axis xyz="0.0 0.0 1.0"/>
    <limit effort="10000" lower="-6.283185" upper="6.283185" velocity="0.01"/>
    <dynamics damping="0" friction="0.0"/>
  </joint>
  <joint name="Rev2" type="revolute">
    <origin rpy="0 0 0" xyz="-4.2e-05 0.009807 0.05"/>
    <parent link="Link1_1"/>
    <child link="Link2_1"/>
    <axis xyz="0.0 -1.0 0.0"/>
    <limit effort="10000" lower="-1.396263" upper="1.396263" velocity="0.01"/>
    <dynamics damping="0" friction="0.0"/>
  </joint>
  <joint name="Rev3" type="revolute">
    <origin rpy="0 0 0" xyz="0.0 0.0 0.3"/>
    <parent link="Link2_1"/>
    <child link="Link3_1"/>
    <axis xyz="0.0 -1.0 0.0"/>
    <limit effort="10000" lower="-2.792527" upper="2.792527" velocity="0.01"/>
    <dynamics damping="0" friction="0.0"/>
  </joint>
  <joint name="Rev4" type="revolute">
    <origin rpy="0 0 0" xyz="6.6e-05 0.0 0.25"/>
    <parent link="Link3_1"/>
    <child link="Link4_1"/>
    <axis xyz="0.0 -1.0 0.0"/>
    <limit effort="10000" lower="-2.617994" upper="2.617994" velocity="0.01"/>
    <dynamics damping="0" friction="0.0"/>
  </joint>
  <link name="world"/>
  <link name="palm">
    <visual>
      <geometry>
        <box size="0.15 0.05 0.02"/>
      </geometry>
    </visual>
    <inertial>
      <mass value="0.1"/>
      <inertia ixx="0.001" ixy="0.001" ixz="0.001" iyy="0.001" iyz="0.001" izz="0.001"/>
    </inertial>
    <collision>
      <geometry>
        <box size="0.15 0.05 0.02"/>
      </geometry>
    </collision>
  </link>
  <gazebo reference="palm">
    <mu1>2000</mu1>
    <mu2>2000</mu2>
    <selfCollide>true</selfCollide>
    <gravity>true</gravity>
  </gazebo>
  <joint name="palm_arm_joint" type="fixed">
    <parent link="Link4_1"/>
    <child link="palm"/>
    <origin rpy="0 0 0" xyz="0.0 0 0.15"/>
  </joint>
  <gazebo>
    <plugin filename="libgazebo_ros_control.so" name="gazebo_ros_control">
      <robotNamespace/>
    </plugin>
    <plugin filename="libspring_joint_plugin.so" name="spring_joint_plugin">
      <kConstant> 0.4 </kConstant>
    </plugin>
    <plugin filename="libjoint_controller_plugin.so" name="joint_controller_plugin">
      <jointNamesParam> arm_controller/ </jointNamesParam>
    </plugin>
    <plugin filename="libjoint_force_visualiser_plugin.so" name="joint_force_visualier_plugin">
      <robotNamespace/>
    </plugin>
  </gazebo>
  <!--  MACROS FOR FINGER: LT-->
  <link name="LTseg1">
    <visual>
      <geometry>
        <box size="0.02 0.02 0.0125"/>
      </geometry>
      <origin xyz="0 0 0"/>
      <material name="white"/>
    </visual>
    <inertial>
      <mass value="0.01"/>
      <origin rpy="0 0 0" xyz="0 0 0"/>
      <inertia ixx="4.6354148125e-07" ixy="0.0" ixz="0.0" iyy="4.6354148125e-07" iyz="0.0" izz="6.666664e-07"/>
    </inertial>
    <!--
		<inertial>
			<mass value="0.001"/>
			<inertia ixx="0.000000001" ixy="0.000000001" ixz="0.000000001" iyy="0.000000001" iyz="0.000000001" izz="0.000000001"/>
		</inertial>
		-->
    <collision>
      <geometry>
        <box size="0.02 0.02 0.0125"/>
      </geometry>
      <origin xyz="0 0 0"/>
    </collision>
  </link>
  <gazebo reference="LTseg1">
    <!--plugin name='main_description' filename='libmain_description.so'/>-->
    <mu1>20000</mu1>
    <mu2>20000</mu2>
    <selfCollide>true</selfCollide>
    <gravity>true</gravity>
  </gazebo>
  <joint name="palm_LTseg1_joint" type="revolute">
    <axis xyz="1 0 0"/>
    <limit effort="2.0" lower="-0.0" upper="0.0" velocity="0.0001"/>
    <!--<dynamics damping="0.05" friction="0.0"/>-->
    <origin rpy="-0.3 0 0" xyz="0.04 0.04 0.03"/>
    <parent link="palm"/>
    <child link="LTseg1"/>
  </joint>
  <transmission name="palm_LTseg1_trans">
    <type>transmission_interface/SimpleTransmission</type>
    <actuator name="palm_LTseg1_motor">
      <mechanicalReduction>1</mechanicalReduction>
    </actuator>
    <joint name="palm_LTseg1_joint">
      <hardwareInterface>hardware_interface/EffortJointInterface</hardwareInterface>
    </joint>
  </transmission>
  <gazebo reference="palm_LTseg1_joint">
    <mu1 value="200.0"/>
    <mu2 value="100.0"/>
    <kp value="10000000.0"/>
    <kd value="1.0"/>
    <material>Gazebo/Grey</material>
  </gazebo>
  <link name="LTseg2">
    <visual>
      <geometry>
        <box size="0.0191666666667 0.0191666666667 0.0125"/>
      </geometry>
      <origin xyz="0 0 0"/>
      <material name="white"/>
    </visual>
    <inertial>
      <mass value="0.01"/>
      <origin rpy="0 0 0" xyz="0 0 0"/>
      <inertia ixx="4.36342418057e-07" ixy="0.0" ixz="0.0" iyy="4.36342418057e-07" iyz="0.0" izz="6.12268273613e-07"/>
    </inertial>
    <!--
		<inertial>
			<mass value="0.001"/>
			<inertia ixx="0.000000001" ixy="0.000000001" ixz="0.000000001" iyy="0.000000001" iyz="0.000000001" izz="0.000000001"/>
		</inertial>
		-->
    <collision>
      <geometry>
        <box size="0.0191666666667 0.0191666666667 0.0125"/>
      </geometry>
      <origin xyz="0 0 0"/>
    </collision>
  </link>
  <gazebo reference="LTseg2">
    <!--plugin name='main_description' filename='libmain_description.so'/>-->
    <mu1>20000</mu1>
    <mu2>20000</mu2>
    <selfCollide>true</selfCollide>
    <gravity>true</gravity>
  </gazebo>
  <joint name="LTseg1_LTseg2_joint" type="revolute">
    <axis xyz="1 0 0"/>
    <limit effort="2.0" lower="-2" upper="2" velocity="0.001"/>
    <dynamics damping="0.02" friction="0.0"/>
    <origin rpy="0 0 0" xyz="0 0 0.0125"/>
    <parent link="LTseg1"/>
    <child link="LTseg2"/>
  </joint>
  <gazebo reference="LTseg1_LTseg2_joint">
    <implicitSpringDamper>True</implicitSpringDamper>
  </gazebo>
  <transmission name="LTseg1_LTseg2_trans">
    <type>transmission_interface/SimpleTransmission</type>
    <actuator name="LTseg1_LTseg2_motor">
      <mechanicalReduction>1</mechanicalReduction>
    </actuator>
    <joint name="LTseg1_LTseg2_joint">
      <hardwareInterface>hardware_interface/EffortJointInterface</hardwareInterface>
    </joint>
  </transmission>
  <gazebo reference="LTseg1_LTseg2_joint">
    <mu1 value="200.0"/>
    <mu2 value="100.0"/>
    <kp value="10000000.0"/>
    <kd value="1.0"/>
    <material>Gazebo/Grey</material>
  </gazebo>
  <link name="LTseg3">
    <visual>
      <geometry>
        <box size="0.0183333333333 0.0183333333333 0.0125"/>
      </geometry>
      <origin xyz="0 0 0"/>
      <material name="white"/>
    </visual>
    <inertial>
      <mass value="0.01"/>
      <origin rpy="0 0 0" xyz="0 0 0"/>
      <inertia ixx="4.10300761805e-07" ixy="0.0" ixz="0.0" iyy="4.10300761805e-07" iyz="0.0" izz="5.60184961109e-07"/>
    </inertial>
    <!--
		<inertial>
			<mass value="0.001"/>
			<inertia ixx="0.000000001" ixy="0.000000001" ixz="0.000000001" iyy="0.000000001" iyz="0.000000001" izz="0.000000001"/>
		</inertial>
		-->
    <collision>
      <geometry>
        <box size="0.0183333333333 0.0183333333333 0.0125"/>
      </geometry>
      <origin xyz="0 0 0"/>
    </collision>
  </link>
  <gazebo reference="LTseg3">
    <!--plugin name='main_description' filename='libmain_description.so'/>-->
    <mu1>20000</mu1>
    <mu2>20000</mu2>
    <selfCollide>true</selfCollide>
    <gravity>true</gravity>
  </gazebo>
  <joint name="LTseg2_LTseg3_joint" type="revolute">
    <axis xyz="1 0 0"/>
    <limit effort="2.0" lower="-2" upper="2" velocity="0.001"/>
    <dynamics damping="0.02" friction="0.0"/>
    <origin rpy="0 0 0" xyz="0 0 0.0125"/>
    <parent link="LTseg2"/>
    <child link="LTseg3"/>
  </joint>
  <gazebo reference="LTseg2_LTseg3_joint">
    <implicitSpringDamper>True</implicitSpringDamper>
  </gazebo>
  <transmission name="LTseg2_LTseg3_trans">
    <type>transmission_interface/SimpleTransmission</type>
    <actuator name="LTseg2_LTseg3_motor">
      <mechanicalReduction>1</mechanicalReduction>
    </actuator>
    <joint name="LTseg2_LTseg3_joint">
      <hardwareInterface>hardware_interface/EffortJointInterface</hardwareInterface>
    </joint>
  </transmission>
  <gazebo reference="LTseg2_LTseg3_joint">
    <mu1 value="200.0"/>
    <mu2 value="100.0"/>
    <kp value="10000000.0"/>
    <kd value="1.0"/>
    <material>Gazebo/Grey</material>
  </gazebo>
  <link name="LTseg4">
    <visual>
      <geometry>
        <box size="0.0175 0.0175 0.0125"/>
      </geometry>
      <origin xyz="0 0 0"/>
      <material name="white"/>
    </visual>
    <inertial>
      <mass value="0.01"/>
      <origin rpy="0 0 0" xyz="0 0 0"/>
      <inertia ixx="3.854165125e-07" ixy="0.0" ixz="0.0" iyy="3.854165125e-07" iyz="0.0" izz="5.104164625e-07"/>
    </inertial>
    <!--
		<inertial>
			<mass value="0.001"/>
			<inertia ixx="0.000000001" ixy="0.000000001" ixz="0.000000001" iyy="0.000000001" iyz="0.000000001" izz="0.000000001"/>
		</inertial>
		-->
    <collision>
      <geometry>
        <box size="0.0175 0.0175 0.0125"/>
      </geometry>
      <origin xyz="0 0 0"/>
    </collision>
  </link>
  <gazebo reference="LTseg4">
    <!--plugin name='main_description' filename='libmain_description.so'/>-->
    <mu1>20000</mu1>
    <mu2>20000</mu2>
    <selfCollide>true</selfCollide>
    <gravity>true</gravity>
  </gazebo>
  <joint name="LTseg3_LTseg4_joint" type="revolute">
    <axis xyz="1 0 0"/>
    <limit effort="2.0" lower="-2" upper="2" velocity="0.001"/>
    <dynamics damping="0.02" friction="0.0"/>
    <origin rpy="0 0 0" xyz="0 0 0.0125"/>
    <parent link="LTseg3"/>
    <child link="LTseg4"/>
  </joint>
  <gazebo reference="LTseg3_LTseg4_joint">
    <implicitSpringDamper>True</implicitSpringDamper>
  </gazebo>
  <transmission name="LTseg3_LTseg4_trans">
    <type>transmission_interface/SimpleTransmission</type>
    <actuator name="LTseg3_LTseg4_motor">
      <mechanicalReduction>1</mechanicalReduction>
    </actuator>
    <joint name="LTseg3_LTseg4_joint">
      <hardwareInterface>hardware_interface/EffortJointInterface</hardwareInterface>
    </joint>
  </transmission>
  <gazebo reference="LTseg3_LTseg4_joint">
    <mu1 value="200.0"/>
    <mu2 value="100.0"/>
    <kp value="10000000.0"/>
    <kd value="1.0"/>
    <material>Gazebo/Grey</material>
  </gazebo>
  <link name="LTseg5">
    <visual>
      <geometry>
        <box size="0.0166666666667 0.0166666666667 0.0125"/>
      </geometry>
      <origin xyz="0 0 0"/>
      <material name="white"/>
    </visual>
    <inertial>
      <mass value="0.01"/>
      <origin rpy="0 0 0" xyz="0 0 0"/>
      <inertia ixx="3.6168967014e-07" ixy="0.0" ixz="0.0" iyy="3.6168967014e-07" iyz="0.0" izz="4.6296277778e-07"/>
    </inertial>
    <!--
		<inertial>
			<mass value="0.001"/>
			<inertia ixx="0.000000001" ixy="0.000000001" ixz="0.000000001" iyy="0.000000001" iyz="0.000000001" izz="0.000000001"/>
		</inertial>
		-->
    <collision>
      <geometry>
        <box size="0.0166666666667 0.0166666666667 0.0125"/>
      </geometry>
      <origin xyz="0 0 0"/>
    </collision>
  </link>
  <gazebo reference="LTseg5">
    <!--plugin name='main_description' filename='libmain_description.so'/>-->
    <mu1>20000</mu1>
    <mu2>20000</mu2>
    <selfCollide>true</selfCollide>
    <gravity>true</gravity>
  </gazebo>
  <joint name="LTseg4_LTseg5_joint" type="revolute">
    <axis xyz="1 0 0"/>
    <limit effort="2.0" lower="-2" upper="2" velocity="0.001"/>
    <dynamics damping="0.02" friction="0.0"/>
    <origin rpy="0 0 0" xyz="0 0 0.0125"/>
    <parent link="LTseg4"/>
    <child link="LTseg5"/>
  </joint>
  <gazebo reference="LTseg4_LTseg5_joint">
    <implicitSpringDamper>True</implicitSpringDamper>
  </gazebo>
  <transmission name="LTseg4_LTseg5_trans">
    <type>transmission_interface/SimpleTransmission</type>
    <actuator name="LTseg4_LTseg5_motor">
      <mechanicalReduction>1</mechanicalReduction>
    </actuator>
    <joint name="LTseg4_LTseg5_joint">
      <hardwareInterface>hardware_interface/EffortJointInterface</hardwareInterface>
    </joint>
  </transmission>
  <gazebo reference="LTseg4_LTseg5_joint">
    <mu1 value="200.0"/>
    <mu2 value="100.0"/>
    <kp value="10000000.0"/>
    <kd value="1.0"/>
    <material>Gazebo/Grey</material>
  </gazebo>
  <link name="LTseg6">
    <visual>
      <geometry>
        <box size="0.0158333333333 0.0158333333333 0.0125"/>
      </geometry>
      <origin xyz="0 0 0"/>
      <material name="white"/>
    </visual>
    <inertial>
      <mass value="0.01"/>
      <origin rpy="0 0 0" xyz="0 0 0"/>
      <inertia ixx="3.39120234721e-07" ixy="0.0" ixz="0.0" iyy="3.39120234721e-07" iyz="0.0" izz="4.17823906943e-07"/>
    </inertial>
    <!--
		<inertial>
			<mass value="0.001"/>
			<inertia ixx="0.000000001" ixy="0.000000001" ixz="0.000000001" iyy="0.000000001" iyz="0.000000001" izz="0.000000001"/>
		</inertial>
		-->
    <collision>
      <geometry>
        <box size="0.0158333333333 0.0158333333333 0.0125"/>
      </geometry>
      <origin xyz="0 0 0"/>
    </collision>
  </link>
  <gazebo reference="LTseg6">
    <!--plugin name='main_description' filename='libmain_description.so'/>-->
    <mu1>20000</mu1>
    <mu2>20000</mu2>
    <selfCollide>true</selfCollide>
    <gravity>true</gravity>
  </gazebo>
  <joint name="LTseg5_LTseg6_joint" type="revolute">
    <axis xyz="1 0 0"/>
    <limit effort="2.0" lower="-2" upper="2" velocity="0.001"/>
    <dynamics damping="0.02" friction="0.0"/>
    <origin rpy="0 0 0" xyz="0 0 0.0125"/>
    <parent link="LTseg5"/>
    <child link="LTseg6"/>
  </joint>
  <gazebo reference="LTseg5_LTseg6_joint">
    <implicitSpringDamper>True</implicitSpringDamper>
  </gazebo>
  <transmission name="LTseg5_LTseg6_trans">
    <type>transmission_interface/SimpleTransmission</type>
    <actuator name="LTseg5_LTseg6_motor">
      <mechanicalReduction>1</mechanicalReduction>
    </actuator>
    <joint name="LTseg5_LTseg6_joint">
      <hardwareInterface>hardware_interface/EffortJointInterface</hardwareInterface>
    </joint>
  </transmission>
  <gazebo reference="LTseg5_LTseg6_joint">
    <mu1 value="200.0"/>
    <mu2 value="100.0"/>
    <kp value="10000000.0"/>
    <kd value="1.0"/>
    <material>Gazebo/Grey</material>
  </gazebo>
  <link name="LTseg7">
    <visual>
      <geometry>
        <box size="0.015 0.015 0.0125"/>
      </geometry>
      <origin xyz="0 0 0"/>
      <material name="white"/>
    </visual>
    <inertial>
      <mass value="0.01"/>
      <origin rpy="0 0 0" xyz="0 0 0"/>
      <inertia ixx="3.1770820625e-07" ixy="0.0" ixz="0.0" iyy="3.1770820625e-07" iyz="0.0" izz="3.7499985e-07"/>
    </inertial>
    <!--
		<inertial>
			<mass value="0.001"/>
			<inertia ixx="0.000000001" ixy="0.000000001" ixz="0.000000001" iyy="0.000000001" iyz="0.000000001" izz="0.000000001"/>
		</inertial>
		-->
    <collision>
      <geometry>
        <box size="0.015 0.015 0.0125"/>
      </geometry>
      <origin xyz="0 0 0"/>
    </collision>
  </link>
  <gazebo reference="LTseg7">
    <!--plugin name='main_description' filename='libmain_description.so'/>-->
    <mu1>20000</mu1>
    <mu2>20000</mu2>
    <selfCollide>true</selfCollide>
    <gravity>true</gravity>
  </gazebo>
  <joint name="LTseg6_LTseg7_joint" type="revolute">
    <axis xyz="1 0 0"/>
    <limit effort="2.0" lower="-2" upper="2" velocity="0.001"/>
    <dynamics damping="0.02" friction="0.0"/>
    <origin rpy="0 0 0" xyz="0 0 0.0125"/>
    <parent link="LTseg6"/>
    <child link="LTseg7"/>
  </joint>
  <gazebo reference="LTseg6_LTseg7_joint">
    <implicitSpringDamper>True</implicitSpringDamper>
  </gazebo>
  <transmission name="LTseg6_LTseg7_trans">
    <type>transmission_interface/SimpleTransmission</type>
    <actuator name="LTseg6_LTseg7_motor">
      <mechanicalReduction>1</mechanicalReduction>
    </actuator>
    <joint name="LTseg6_LTseg7_joint">
      <hardwareInterface>hardware_interface/EffortJointInterface</hardwareInterface>
    </joint>
  </transmission>
  <gazebo reference="LTseg6_LTseg7_joint">
    <mu1 value="200.0"/>
    <mu2 value="100.0"/>
    <kp value="10000000.0"/>
    <kd value="1.0"/>
    <material>Gazebo/Grey</material>
  </gazebo>
  <link name="LTseg8">
    <visual>
      <geometry>
        <box size="0.0141666666667 0.0141666666667 0.0125"/>
      </geometry>
      <origin xyz="0 0 0"/>
      <material name="white"/>
    </visual>
    <inertial>
      <mass value="0.01"/>
      <origin rpy="0 0 0" xyz="0 0 0"/>
      <inertia ixx="2.97453584723e-07" ixy="0.0" ixz="0.0" iyy="2.97453584723e-07" iyz="0.0" izz="3.34490606946e-07"/>
    </inertial>
    <!--
		<inertial>
			<mass value="0.001"/>
			<inertia ixx="0.000000001" ixy="0.000000001" ixz="0.000000001" iyy="0.000000001" iyz="0.000000001" izz="0.000000001"/>
		</inertial>
		-->
    <collision>
      <geometry>
        <box size="0.0141666666667 0.0141666666667 0.0125"/>
      </geometry>
      <origin xyz="0 0 0"/>
    </collision>
  </link>
  <gazebo reference="LTseg8">
    <!--plugin name='main_description' filename='libmain_description.so'/>-->
    <mu1>20000</mu1>
    <mu2>20000</mu2>
    <selfCollide>true</selfCollide>
    <gravity>true</gravity>
  </gazebo>
  <joint name="LTseg7_LTseg8_joint" type="revolute">
    <axis xyz="1 0 0"/>
    <limit effort="2.0" lower="-2" upper="2" velocity="0.001"/>
    <dynamics damping="0.02" friction="0.0"/>
    <origin rpy="0 0 0" xyz="0 0 0.0125"/>
    <parent link="LTseg7"/>
    <child link="LTseg8"/>
  </joint>
  <gazebo reference="LTseg7_LTseg8_joint">
    <implicitSpringDamper>True</implicitSpringDamper>
  </gazebo>
  <transmission name="LTseg7_LTseg8_trans">
    <type>transmission_interface/SimpleTransmission</type>
    <actuator name="LTseg7_LTseg8_motor">
      <mechanicalReduction>1</mechanicalReduction>
    </actuator>
    <joint name="LTseg7_LTseg8_joint">
      <hardwareInterface>hardware_interface/EffortJointInterface</hardwareInterface>
    </joint>
  </transmission>
  <gazebo reference="LTseg7_LTseg8_joint">
    <mu1 value="200.0"/>
    <mu2 value="100.0"/>
    <kp value="10000000.0"/>
    <kd value="1.0"/>
    <material>Gazebo/Grey</material>
  </gazebo>
  <link name="LTseg9">
    <visual>
      <geometry>
        <box size="0.0133333333333 0.0133333333333 0.0125"/>
      </geometry>
      <origin xyz="0 0 0"/>
      <material name="white"/>
    </visual>
    <inertial>
      <mass value="0.01"/>
      <origin rpy="0 0 0" xyz="0 0 0"/>
      <inertia ixx="2.78356370138e-07" ixy="0.0" ixz="0.0" iyy="2.78356370138e-07" iyz="0.0" izz="2.96296177776e-07"/>
    </inertial>
    <!--
		<inertial>
			<mass value="0.001"/>
			<inertia ixx="0.000000001" ixy="0.000000001" ixz="0.000000001" iyy="0.000000001" iyz="0.000000001" izz="0.000000001"/>
		</inertial>
		-->
    <collision>
      <geometry>
        <box size="0.0133333333333 0.0133333333333 0.0125"/>
      </geometry>
      <origin xyz="0 0 0"/>
    </collision>
  </link>
  <gazebo reference="LTseg9">
    <!--plugin name='main_description' filename='libmain_description.so'/>-->
    <mu1>20000</mu1>
    <mu2>20000</mu2>
    <selfCollide>true</selfCollide>
    <gravity>true</gravity>
  </gazebo>
  <joint name="LTseg8_LTseg9_joint" type="revolute">
    <axis xyz="1 0 0"/>
    <limit effort="2.0" lower="-2" upper="2" velocity="0.001"/>
    <dynamics damping="0.02" friction="0.0"/>
    <origin rpy="0 0 0" xyz="0 0 0.0125"/>
    <parent link="LTseg8"/>
    <child link="LTseg9"/>
  </joint>
  <gazebo reference="LTseg8_LTseg9_joint">
    <implicitSpringDamper>True</implicitSpringDamper>
  </gazebo>
  <transmission name="LTseg8_LTseg9_trans">
    <type>transmission_interface/SimpleTransmission</type>
    <actuator name="LTseg8_LTseg9_motor">
      <mechanicalReduction>1</mechanicalReduction>
    </actuator>
    <joint name="LTseg8_LTseg9_joint">
      <hardwareInterface>hardware_interface/EffortJointInterface</hardwareInterface>
    </joint>
  </transmission>
  <gazebo reference="LTseg8_LTseg9_joint">
    <mu1 value="200.0"/>
    <mu2 value="100.0"/>
    <kp value="10000000.0"/>
    <kd value="1.0"/>
    <material>Gazebo/Grey</material>
  </gazebo>
  <link name="LTseg10">
    <visual>
      <geometry>
        <box size="0.0125 0.0125 0.0125"/>
      </geometry>
      <origin xyz="0 0 0"/>
      <material name="white"/>
    </visual>
    <inertial>
      <mass value="0.01"/>
      <origin rpy="0 0 0" xyz="0 0 0"/>
      <inertia ixx="2.604165625e-07" ixy="0.0" ixz="0.0" iyy="2.604165625e-07" iyz="0.0" izz="2.604165625e-07"/>
    </inertial>
    <!--
		<inertial>
			<mass value="0.001"/>
			<inertia ixx="0.000000001" ixy="0.000000001" ixz="0.000000001" iyy="0.000000001" iyz="0.000000001" izz="0.000000001"/>
		</inertial>
		-->
    <collision>
      <geometry>
        <box size="0.0125 0.0125 0.0125"/>
      </geometry>
      <origin xyz="0 0 0"/>
    </collision>
  </link>
  <gazebo reference="LTseg10">
    <!--plugin name='main_description' filename='libmain_description.so'/>-->
    <mu1>20000</mu1>
    <mu2>20000</mu2>
    <selfCollide>true</selfCollide>
    <gravity>true</gravity>
  </gazebo>
  <joint name="LTseg9_LTseg10_joint" type="revolute">
    <axis xyz="1 0 0"/>
    <limit effort="2.0" lower="-2" upper="2" velocity="0.001"/>
    <dynamics damping="0.02" friction="0.0"/>
    <origin rpy="0 0 0" xyz="0 0 0.0125"/>
    <parent link="LTseg9"/>
    <child link="LTseg10"/>
  </joint>
  <gazebo reference="LTseg9_LTseg10_joint">
    <implicitSpringDamper>True</implicitSpringDamper>
  </gazebo>
  <transmission name="LTseg9_LTseg10_trans">
    <type>transmission_interface/SimpleTransmission</type>
    <actuator name="LTseg9_LTseg10_motor">
      <mechanicalReduction>1</mechanicalReduction>
    </actuator>
    <joint name="LTseg9_LTseg10_joint">
      <hardwareInterface>hardware_interface/EffortJointInterface</hardwareInterface>
    </joint>
  </transmission>
  <gazebo reference="LTseg9_LTseg10_joint">
    <mu1 value="200.0"/>
    <mu2 value="100.0"/>
    <kp value="10000000.0"/>
    <kd value="1.0"/>
    <material>Gazebo/Grey</material>
  </gazebo>
  <link name="LTseg11">
    <visual>
      <geometry>
        <box size="0.0116666666667 0.0116666666667 0.0125"/>
      </geometry>
      <origin xyz="0 0 0"/>
      <material name="white"/>
    </visual>
    <inertial>
      <mass value="0.01"/>
      <origin rpy="0 0 0" xyz="0 0 0"/>
      <inertia ixx="2.43634161806e-07" ixy="0.0" ixz="0.0" iyy="2.43634161806e-07" iyz="0.0" izz="2.26851761112e-07"/>
    </inertial>
    <!--
		<inertial>
			<mass value="0.001"/>
			<inertia ixx="0.000000001" ixy="0.000000001" ixz="0.000000001" iyy="0.000000001" iyz="0.000000001" izz="0.000000001"/>
		</inertial>
		-->
    <collision>
      <geometry>
        <box size="0.0116666666667 0.0116666666667 0.0125"/>
      </geometry>
      <origin xyz="0 0 0"/>
    </collision>
  </link>
  <gazebo reference="LTseg11">
    <!--plugin name='main_description' filename='libmain_description.so'/>-->
    <mu1>20000</mu1>
    <mu2>20000</mu2>
    <selfCollide>true</selfCollide>
    <gravity>true</gravity>
  </gazebo>
  <joint name="LTseg10_LTseg11_joint" type="revolute">
    <axis xyz="1 0 0"/>
    <limit effort="2.0" lower="-2" upper="2" velocity="0.001"/>
    <dynamics damping="0.02" friction="0.0"/>
    <origin rpy="0 0 0" xyz="0 0 0.0125"/>
    <parent link="LTseg10"/>
    <child link="LTseg11"/>
  </joint>
  <gazebo reference="LTseg10_LTseg11_joint">
    <implicitSpringDamper>True</implicitSpringDamper>
  </gazebo>
  <transmission name="LTseg10_LTseg11_trans">
    <type>transmission_interface/SimpleTransmission</type>
    <actuator name="LTseg10_LTseg11_motor">
      <mechanicalReduction>1</mechanicalReduction>
    </actuator>
    <joint name="LTseg10_LTseg11_joint">
      <hardwareInterface>hardware_interface/EffortJointInterface</hardwareInterface>
    </joint>
  </transmission>
  <gazebo reference="LTseg10_LTseg11_joint">
    <mu1 value="200.0"/>
    <mu2 value="100.0"/>
    <kp value="10000000.0"/>
    <kd value="1.0"/>
    <material>Gazebo/Grey</material>
  </gazebo>
  <link name="LTseg12">
    <visual>
      <geometry>
        <box size="0.0108333333333 0.0108333333333 0.0125"/>
      </geometry>
      <origin xyz="0 0 0"/>
      <material name="white"/>
    </visual>
    <inertial>
      <mass value="0.01"/>
      <origin rpy="0 0 0" xyz="0 0 0"/>
      <inertia ixx="2.28009168055e-07" ixy="0.0" ixz="0.0" iyy="2.28009168055e-07" iyz="0.0" izz="1.9560177361e-07"/>
    </inertial>
    <!--
		<inertial>
			<mass value="0.001"/>
			<inertia ixx="0.000000001" ixy="0.000000001" ixz="0.000000001" iyy="0.000000001" iyz="0.000000001" izz="0.000000001"/>
		</inertial>
		-->
    <collision>
      <geometry>
        <box size="0.0108333333333 0.0108333333333 0.0125"/>
      </geometry>
      <origin xyz="0 0 0"/>
    </collision>
  </link>
  <gazebo reference="LTseg12">
    <!--plugin name='main_description' filename='libmain_description.so'/>-->
    <mu1>20000</mu1>
    <mu2>20000</mu2>
    <selfCollide>true</selfCollide>
    <gravity>true</gravity>
  </gazebo>
  <joint name="LTseg11_LTseg12_joint" type="revolute">
    <axis xyz="1 0 0"/>
    <limit effort="2.0" lower="-2" upper="2" velocity="0.001"/>
    <dynamics damping="0.02" friction="0.0"/>
    <origin rpy="0 0 0" xyz="0 0 0.0125"/>
    <parent link="LTseg11"/>
    <child link="LTseg12"/>
  </joint>
  <gazebo reference="LTseg11_LTseg12_joint">
    <implicitSpringDamper>True</implicitSpringDamper>
  </gazebo>
  <transmission name="LTseg11_LTseg12_trans">
    <type>transmission_interface/SimpleTransmission</type>
    <actuator name="LTseg11_LTseg12_motor">
      <mechanicalReduction>1</mechanicalReduction>
    </actuator>
    <joint name="LTseg11_LTseg12_joint">
      <hardwareInterface>hardware_interface/EffortJointInterface</hardwareInterface>
    </joint>
  </transmission>
  <gazebo reference="LTseg11_LTseg12_joint">
    <mu1 value="200.0"/>
    <mu2 value="100.0"/>
    <kp value="10000000.0"/>
    <kd value="1.0"/>
    <material>Gazebo/Grey</material>
  </gazebo>
  <!--  MACROS FOR FINGER: RT-->
  <link name="RTseg1">
    <visual>
      <geometry>
        <box size="0.02 0.02 0.0125"/>
      </geometry>
      <origin xyz="0 0 0"/>
      <material name="white"/>
    </visual>
    <inertial>
      <mass value="0.01"/>
      <origin rpy="0 0 0" xyz="0 0 0"/>
      <inertia ixx="4.6354148125e-07" ixy="0.0" ixz="0.0" iyy="4.6354148125e-07" iyz="0.0" izz="6.666664e-07"/>
    </inertial>
    <!--
		<inertial>
			<mass value="0.001"/>
			<inertia ixx="0.000000001" ixy="0.000000001" ixz="0.000000001" iyy="0.000000001" iyz="0.000000001" izz="0.000000001"/>
		</inertial>
		-->
    <collision>
      <geometry>
        <box size="0.02 0.02 0.0125"/>
      </geometry>
      <origin xyz="0 0 0"/>
    </collision>
  </link>
  <gazebo reference="RTseg1">
    <!--plugin name='main_description' filename='libmain_description.so'/>-->
    <mu1>20000</mu1>
    <mu2>20000</mu2>
    <selfCollide>true</selfCollide>
    <gravity>true</gravity>
  </gazebo>
  <joint name="palm_RTseg1_joint" type="revolute">
    <axis xyz="1 0 0"/>
    <limit effort="2.0" lower="-0.0" upper="0.0" velocity="0.0001"/>
    <!--<dynamics damping="0.05" friction="0.0"/>-->
    <origin rpy="-0.3 0 3.14159" xyz="0.04 -0.04 0.03"/>
    <parent link="palm"/>
    <child link="RTseg1"/>
  </joint>
  <transmission name="palm_RTseg1_trans">
    <type>transmission_interface/SimpleTransmission</type>
    <actuator name="palm_RTseg1_motor">
      <mechanicalReduction>1</mechanicalReduction>
    </actuator>
    <joint name="palm_RTseg1_joint">
      <hardwareInterface>hardware_interface/EffortJointInterface</hardwareInterface>
    </joint>
  </transmission>
  <gazebo reference="palm_RTseg1_joint">
    <mu1 value="200.0"/>
    <mu2 value="100.0"/>
    <kp value="10000000.0"/>
    <kd value="1.0"/>
    <material>Gazebo/Grey</material>
  </gazebo>
  <link name="RTseg2">
    <visual>
      <geometry>
        <box size="0.0191666666667 0.0191666666667 0.0125"/>
      </geometry>
      <origin xyz="0 0 0"/>
      <material name="white"/>
    </visual>
    <inertial>
      <mass value="0.01"/>
      <origin rpy="0 0 0" xyz="0 0 0"/>
      <inertia ixx="4.36342418057e-07" ixy="0.0" ixz="0.0" iyy="4.36342418057e-07" iyz="0.0" izz="6.12268273613e-07"/>
    </inertial>
    <!--
		<inertial>
			<mass value="0.001"/>
			<inertia ixx="0.000000001" ixy="0.000000001" ixz="0.000000001" iyy="0.000000001" iyz="0.000000001" izz="0.000000001"/>
		</inertial>
		-->
    <collision>
      <geometry>
        <box size="0.0191666666667 0.0191666666667 0.0125"/>
      </geometry>
      <origin xyz="0 0 0"/>
    </collision>
  </link>
  <gazebo reference="RTseg2">
    <!--plugin name='main_description' filename='libmain_description.so'/>-->
    <mu1>20000</mu1>
    <mu2>20000</mu2>
    <selfCollide>true</selfCollide>
    <gravity>true</gravity>
  </gazebo>
  <joint name="RTseg1_RTseg2_joint" type="revolute">
    <axis xyz="1 0 0"/>
    <limit effort="2.0" lower="-2" upper="2" velocity="0.001"/>
    <dynamics damping="0.02" friction="0.0"/>
    <origin rpy="0 0 0" xyz="0 0 0.0125"/>
    <parent link="RTseg1"/>
    <child link="RTseg2"/>
  </joint>
  <gazebo reference="RTseg1_RTseg2_joint">
    <implicitSpringDamper>True</implicitSpringDamper>
  </gazebo>
  <transmission name="RTseg1_RTseg2_trans">
    <type>transmission_interface/SimpleTransmission</type>
    <actuator name="RTseg1_RTseg2_motor">
      <mechanicalReduction>1</mechanicalReduction>
    </actuator>
    <joint name="RTseg1_RTseg2_joint">
      <hardwareInterface>hardware_interface/EffortJointInterface</hardwareInterface>
    </joint>
  </transmission>
  <gazebo reference="RTseg1_RTseg2_joint">
    <mu1 value="200.0"/>
    <mu2 value="100.0"/>
    <kp value="10000000.0"/>
    <kd value="1.0"/>
    <material>Gazebo/Grey</material>
  </gazebo>
  <link name="RTseg3">
    <visual>
      <geometry>
        <box size="0.0183333333333 0.0183333333333 0.0125"/>
      </geometry>
      <origin xyz="0 0 0"/>
      <material name="white"/>
    </visual>
    <inertial>
      <mass value="0.01"/>
      <origin rpy="0 0 0" xyz="0 0 0"/>
      <inertia ixx="4.10300761805e-07" ixy="0.0" ixz="0.0" iyy="4.10300761805e-07" iyz="0.0" izz="5.60184961109e-07"/>
    </inertial>
    <!--
		<inertial>
			<mass value="0.001"/>
			<inertia ixx="0.000000001" ixy="0.000000001" ixz="0.000000001" iyy="0.000000001" iyz="0.000000001" izz="0.000000001"/>
		</inertial>
		-->
    <collision>
      <geometry>
        <box size="0.0183333333333 0.0183333333333 0.0125"/>
      </geometry>
      <origin xyz="0 0 0"/>
    </collision>
  </link>
  <gazebo reference="RTseg3">
    <!--plugin name='main_description' filename='libmain_description.so'/>-->
    <mu1>20000</mu1>
    <mu2>20000</mu2>
    <selfCollide>true</selfCollide>
    <gravity>true</gravity>
  </gazebo>
  <joint name="RTseg2_RTseg3_joint" type="revolute">
    <axis xyz="1 0 0"/>
    <limit effort="2.0" lower="-2" upper="2" velocity="0.001"/>
    <dynamics damping="0.02" friction="0.0"/>
    <origin rpy="0 0 0" xyz="0 0 0.0125"/>
    <parent link="RTseg2"/>
    <child link="RTseg3"/>
  </joint>
  <gazebo reference="RTseg2_RTseg3_joint">
    <implicitSpringDamper>True</implicitSpringDamper>
  </gazebo>
  <transmission name="RTseg2_RTseg3_trans">
    <type>transmission_interface/SimpleTransmission</type>
    <actuator name="RTseg2_RTseg3_motor">
      <mechanicalReduction>1</mechanicalReduction>
    </actuator>
    <joint name="RTseg2_RTseg3_joint">
      <hardwareInterface>hardware_interface/EffortJointInterface</hardwareInterface>
    </joint>
  </transmission>
  <gazebo reference="RTseg2_RTseg3_joint">
    <mu1 value="200.0"/>
    <mu2 value="100.0"/>
    <kp value="10000000.0"/>
    <kd value="1.0"/>
    <material>Gazebo/Grey</material>
  </gazebo>
  <link name="RTseg4">
    <visual>
      <geometry>
        <box size="0.0175 0.0175 0.0125"/>
      </geometry>
      <origin xyz="0 0 0"/>
      <material name="white"/>
    </visual>
    <inertial>
      <mass value="0.01"/>
      <origin rpy="0 0 0" xyz="0 0 0"/>
      <inertia ixx="3.854165125e-07" ixy="0.0" ixz="0.0" iyy="3.854165125e-07" iyz="0.0" izz="5.104164625e-07"/>
    </inertial>
    <!--
		<inertial>
			<mass value="0.001"/>
			<inertia ixx="0.000000001" ixy="0.000000001" ixz="0.000000001" iyy="0.000000001" iyz="0.000000001" izz="0.000000001"/>
		</inertial>
		-->
    <collision>
      <geometry>
        <box size="0.0175 0.0175 0.0125"/>
      </geometry>
      <origin xyz="0 0 0"/>
    </collision>
  </link>
  <gazebo reference="RTseg4">
    <!--plugin name='main_description' filename='libmain_description.so'/>-->
    <mu1>20000</mu1>
    <mu2>20000</mu2>
    <selfCollide>true</selfCollide>
    <gravity>true</gravity>
  </gazebo>
  <joint name="RTseg3_RTseg4_joint" type="revolute">
    <axis xyz="1 0 0"/>
    <limit effort="2.0" lower="-2" upper="2" velocity="0.001"/>
    <dynamics damping="0.02" friction="0.0"/>
    <origin rpy="0 0 0" xyz="0 0 0.0125"/>
    <parent link="RTseg3"/>
    <child link="RTseg4"/>
  </joint>
  <gazebo reference="RTseg3_RTseg4_joint">
    <implicitSpringDamper>True</implicitSpringDamper>
  </gazebo>
  <transmission name="RTseg3_RTseg4_trans">
    <type>transmission_interface/SimpleTransmission</type>
    <actuator name="RTseg3_RTseg4_motor">
      <mechanicalReduction>1</mechanicalReduction>
    </actuator>
    <joint name="RTseg3_RTseg4_joint">
      <hardwareInterface>hardware_interface/EffortJointInterface</hardwareInterface>
    </joint>
  </transmission>
  <gazebo reference="RTseg3_RTseg4_joint">
    <mu1 value="200.0"/>
    <mu2 value="100.0"/>
    <kp value="10000000.0"/>
    <kd value="1.0"/>
    <material>Gazebo/Grey</material>
  </gazebo>
  <link name="RTseg5">
    <visual>
      <geometry>
        <box size="0.0166666666667 0.0166666666667 0.0125"/>
      </geometry>
      <origin xyz="0 0 0"/>
      <material name="white"/>
    </visual>
    <inertial>
      <mass value="0.01"/>
      <origin rpy="0 0 0" xyz="0 0 0"/>
      <inertia ixx="3.6168967014e-07" ixy="0.0" ixz="0.0" iyy="3.6168967014e-07" iyz="0.0" izz="4.6296277778e-07"/>
    </inertial>
    <!--
		<inertial>
			<mass value="0.001"/>
			<inertia ixx="0.000000001" ixy="0.000000001" ixz="0.000000001" iyy="0.000000001" iyz="0.000000001" izz="0.000000001"/>
		</inertial>
		-->
    <collision>
      <geometry>
        <box size="0.0166666666667 0.0166666666667 0.0125"/>
      </geometry>
      <origin xyz="0 0 0"/>
    </collision>
  </link>
  <gazebo reference="RTseg5">
    <!--plugin name='main_description' filename='libmain_description.so'/>-->
    <mu1>20000</mu1>
    <mu2>20000</mu2>
    <selfCollide>true</selfCollide>
    <gravity>true</gravity>
  </gazebo>
  <joint name="RTseg4_RTseg5_joint" type="revolute">
    <axis xyz="1 0 0"/>
    <limit effort="2.0" lower="-2" upper="2" velocity="0.001"/>
    <dynamics damping="0.02" friction="0.0"/>
    <origin rpy="0 0 0" xyz="0 0 0.0125"/>
    <parent link="RTseg4"/>
    <child link="RTseg5"/>
  </joint>
  <gazebo reference="RTseg4_RTseg5_joint">
    <implicitSpringDamper>True</implicitSpringDamper>
  </gazebo>
  <transmission name="RTseg4_RTseg5_trans">
    <type>transmission_interface/SimpleTransmission</type>
    <actuator name="RTseg4_RTseg5_motor">
      <mechanicalReduction>1</mechanicalReduction>
    </actuator>
    <joint name="RTseg4_RTseg5_joint">
      <hardwareInterface>hardware_interface/EffortJointInterface</hardwareInterface>
    </joint>
  </transmission>
  <gazebo reference="RTseg4_RTseg5_joint">
    <mu1 value="200.0"/>
    <mu2 value="100.0"/>
    <kp value="10000000.0"/>
    <kd value="1.0"/>
    <material>Gazebo/Grey</material>
  </gazebo>
  <link name="RTseg6">
    <visual>
      <geometry>
        <box size="0.0158333333333 0.0158333333333 0.0125"/>
      </geometry>
      <origin xyz="0 0 0"/>
      <material name="white"/>
    </visual>
    <inertial>
      <mass value="0.01"/>
      <origin rpy="0 0 0" xyz="0 0 0"/>
      <inertia ixx="3.39120234721e-07" ixy="0.0" ixz="0.0" iyy="3.39120234721e-07" iyz="0.0" izz="4.17823906943e-07"/>
    </inertial>
    <!--
		<inertial>
			<mass value="0.001"/>
			<inertia ixx="0.000000001" ixy="0.000000001" ixz="0.000000001" iyy="0.000000001" iyz="0.000000001" izz="0.000000001"/>
		</inertial>
		-->
    <collision>
      <geometry>
        <box size="0.0158333333333 0.0158333333333 0.0125"/>
      </geometry>
      <origin xyz="0 0 0"/>
    </collision>
  </link>
  <gazebo reference="RTseg6">
    <!--plugin name='main_description' filename='libmain_description.so'/>-->
    <mu1>20000</mu1>
    <mu2>20000</mu2>
    <selfCollide>true</selfCollide>
    <gravity>true</gravity>
  </gazebo>
  <joint name="RTseg5_RTseg6_joint" type="revolute">
    <axis xyz="1 0 0"/>
    <limit effort="2.0" lower="-2" upper="2" velocity="0.001"/>
    <dynamics damping="0.02" friction="0.0"/>
    <origin rpy="0 0 0" xyz="0 0 0.0125"/>
    <parent link="RTseg5"/>
    <child link="RTseg6"/>
  </joint>
  <gazebo reference="RTseg5_RTseg6_joint">
    <implicitSpringDamper>True</implicitSpringDamper>
  </gazebo>
  <transmission name="RTseg5_RTseg6_trans">
    <type>transmission_interface/SimpleTransmission</type>
    <actuator name="RTseg5_RTseg6_motor">
      <mechanicalReduction>1</mechanicalReduction>
    </actuator>
    <joint name="RTseg5_RTseg6_joint">
      <hardwareInterface>hardware_interface/EffortJointInterface</hardwareInterface>
    </joint>
  </transmission>
  <gazebo reference="RTseg5_RTseg6_joint">
    <mu1 value="200.0"/>
    <mu2 value="100.0"/>
    <kp value="10000000.0"/>
    <kd value="1.0"/>
    <material>Gazebo/Grey</material>
  </gazebo>
  <link name="RTseg7">
    <visual>
      <geometry>
        <box size="0.015 0.015 0.0125"/>
      </geometry>
      <origin xyz="0 0 0"/>
      <material name="white"/>
    </visual>
    <inertial>
      <mass value="0.01"/>
      <origin rpy="0 0 0" xyz="0 0 0"/>
      <inertia ixx="3.1770820625e-07" ixy="0.0" ixz="0.0" iyy="3.1770820625e-07" iyz="0.0" izz="3.7499985e-07"/>
    </inertial>
    <!--
		<inertial>
			<mass value="0.001"/>
			<inertia ixx="0.000000001" ixy="0.000000001" ixz="0.000000001" iyy="0.000000001" iyz="0.000000001" izz="0.000000001"/>
		</inertial>
		-->
    <collision>
      <geometry>
        <box size="0.015 0.015 0.0125"/>
      </geometry>
      <origin xyz="0 0 0"/>
    </collision>
  </link>
  <gazebo reference="RTseg7">
    <!--plugin name='main_description' filename='libmain_description.so'/>-->
    <mu1>20000</mu1>
    <mu2>20000</mu2>
    <selfCollide>true</selfCollide>
    <gravity>true</gravity>
  </gazebo>
  <joint name="RTseg6_RTseg7_joint" type="revolute">
    <axis xyz="1 0 0"/>
    <limit effort="2.0" lower="-2" upper="2" velocity="0.001"/>
    <dynamics damping="0.02" friction="0.0"/>
    <origin rpy="0 0 0" xyz="0 0 0.0125"/>
    <parent link="RTseg6"/>
    <child link="RTseg7"/>
  </joint>
  <gazebo reference="RTseg6_RTseg7_joint">
    <implicitSpringDamper>True</implicitSpringDamper>
  </gazebo>
  <transmission name="RTseg6_RTseg7_trans">
    <type>transmission_interface/SimpleTransmission</type>
    <actuator name="RTseg6_RTseg7_motor">
      <mechanicalReduction>1</mechanicalReduction>
    </actuator>
    <joint name="RTseg6_RTseg7_joint">
      <hardwareInterface>hardware_interface/EffortJointInterface</hardwareInterface>
    </joint>
  </transmission>
  <gazebo reference="RTseg6_RTseg7_joint">
    <mu1 value="200.0"/>
    <mu2 value="100.0"/>
    <kp value="10000000.0"/>
    <kd value="1.0"/>
    <material>Gazebo/Grey</material>
  </gazebo>
  <link name="RTseg8">
    <visual>
      <geometry>
        <box size="0.0141666666667 0.0141666666667 0.0125"/>
      </geometry>
      <origin xyz="0 0 0"/>
      <material name="white"/>
    </visual>
    <inertial>
      <mass value="0.01"/>
      <origin rpy="0 0 0" xyz="0 0 0"/>
      <inertia ixx="2.97453584723e-07" ixy="0.0" ixz="0.0" iyy="2.97453584723e-07" iyz="0.0" izz="3.34490606946e-07"/>
    </inertial>
    <!--
		<inertial>
			<mass value="0.001"/>
			<inertia ixx="0.000000001" ixy="0.000000001" ixz="0.000000001" iyy="0.000000001" iyz="0.000000001" izz="0.000000001"/>
		</inertial>
		-->
    <collision>
      <geometry>
        <box size="0.0141666666667 0.0141666666667 0.0125"/>
      </geometry>
      <origin xyz="0 0 0"/>
    </collision>
  </link>
  <gazebo reference="RTseg8">
    <!--plugin name='main_description' filename='libmain_description.so'/>-->
    <mu1>20000</mu1>
    <mu2>20000</mu2>
    <selfCollide>true</selfCollide>
    <gravity>true</gravity>
  </gazebo>
  <joint name="RTseg7_RTseg8_joint" type="revolute">
    <axis xyz="1 0 0"/>
    <limit effort="2.0" lower="-2" upper="2" velocity="0.001"/>
    <dynamics damping="0.02" friction="0.0"/>
    <origin rpy="0 0 0" xyz="0 0 0.0125"/>
    <parent link="RTseg7"/>
    <child link="RTseg8"/>
  </joint>
  <gazebo reference="RTseg7_RTseg8_joint">
    <implicitSpringDamper>True</implicitSpringDamper>
  </gazebo>
  <transmission name="RTseg7_RTseg8_trans">
    <type>transmission_interface/SimpleTransmission</type>
    <actuator name="RTseg7_RTseg8_motor">
      <mechanicalReduction>1</mechanicalReduction>
    </actuator>
    <joint name="RTseg7_RTseg8_joint">
      <hardwareInterface>hardware_interface/EffortJointInterface</hardwareInterface>
    </joint>
  </transmission>
  <gazebo reference="RTseg7_RTseg8_joint">
    <mu1 value="200.0"/>
    <mu2 value="100.0"/>
    <kp value="10000000.0"/>
    <kd value="1.0"/>
    <material>Gazebo/Grey</material>
  </gazebo>
  <link name="RTseg9">
    <visual>
      <geometry>
        <box size="0.0133333333333 0.0133333333333 0.0125"/>
      </geometry>
      <origin xyz="0 0 0"/>
      <material name="white"/>
    </visual>
    <inertial>
      <mass value="0.01"/>
      <origin rpy="0 0 0" xyz="0 0 0"/>
      <inertia ixx="2.78356370138e-07" ixy="0.0" ixz="0.0" iyy="2.78356370138e-07" iyz="0.0" izz="2.96296177776e-07"/>
    </inertial>
    <!--
		<inertial>
			<mass value="0.001"/>
			<inertia ixx="0.000000001" ixy="0.000000001" ixz="0.000000001" iyy="0.000000001" iyz="0.000000001" izz="0.000000001"/>
		</inertial>
		-->
    <collision>
      <geometry>
        <box size="0.0133333333333 0.0133333333333 0.0125"/>
      </geometry>
      <origin xyz="0 0 0"/>
    </collision>
  </link>
  <gazebo reference="RTseg9">
    <!--plugin name='main_description' filename='libmain_description.so'/>-->
    <mu1>20000</mu1>
    <mu2>20000</mu2>
    <selfCollide>true</selfCollide>
    <gravity>true</gravity>
  </gazebo>
  <joint name="RTseg8_RTseg9_joint" type="revolute">
    <axis xyz="1 0 0"/>
    <limit effort="2.0" lower="-2" upper="2" velocity="0.001"/>
    <dynamics damping="0.02" friction="0.0"/>
    <origin rpy="0 0 0" xyz="0 0 0.0125"/>
    <parent link="RTseg8"/>
    <child link="RTseg9"/>
  </joint>
  <gazebo reference="RTseg8_RTseg9_joint">
    <implicitSpringDamper>True</implicitSpringDamper>
  </gazebo>
  <transmission name="RTseg8_RTseg9_trans">
    <type>transmission_interface/SimpleTransmission</type>
    <actuator name="RTseg8_RTseg9_motor">
      <mechanicalReduction>1</mechanicalReduction>
    </actuator>
    <joint name="RTseg8_RTseg9_joint">
      <hardwareInterface>hardware_interface/EffortJointInterface</hardwareInterface>
    </joint>
  </transmission>
  <gazebo reference="RTseg8_RTseg9_joint">
    <mu1 value="200.0"/>
    <mu2 value="100.0"/>
    <kp value="10000000.0"/>
    <kd value="1.0"/>
    <material>Gazebo/Grey</material>
  </gazebo>
  <link name="RTseg10">
    <visual>
      <geometry>
        <box size="0.0125 0.0125 0.0125"/>
      </geometry>
      <origin xyz="0 0 0"/>
      <material name="white"/>
    </visual>
    <inertial>
      <mass value="0.01"/>
      <origin rpy="0 0 0" xyz="0 0 0"/>
      <inertia ixx="2.604165625e-07" ixy="0.0" ixz="0.0" iyy="2.604165625e-07" iyz="0.0" izz="2.604165625e-07"/>
    </inertial>
    <!--
		<inertial>
			<mass value="0.001"/>
			<inertia ixx="0.000000001" ixy="0.000000001" ixz="0.000000001" iyy="0.000000001" iyz="0.000000001" izz="0.000000001"/>
		</inertial>
		-->
    <collision>
      <geometry>
        <box size="0.0125 0.0125 0.0125"/>
      </geometry>
      <origin xyz="0 0 0"/>
    </collision>
  </link>
  <gazebo reference="RTseg10">
    <!--plugin name='main_description' filename='libmain_description.so'/>-->
    <mu1>20000</mu1>
    <mu2>20000</mu2>
    <selfCollide>true</selfCollide>
    <gravity>true</gravity>
  </gazebo>
  <joint name="RTseg9_RTseg10_joint" type="revolute">
    <axis xyz="1 0 0"/>
    <limit effort="2.0" lower="-2" upper="2" velocity="0.001"/>
    <dynamics damping="0.02" friction="0.0"/>
    <origin rpy="0 0 0" xyz="0 0 0.0125"/>
    <parent link="RTseg9"/>
    <child link="RTseg10"/>
  </joint>
  <gazebo reference="RTseg9_RTseg10_joint">
    <implicitSpringDamper>True</implicitSpringDamper>
  </gazebo>
  <transmission name="RTseg9_RTseg10_trans">
    <type>transmission_interface/SimpleTransmission</type>
    <actuator name="RTseg9_RTseg10_motor">
      <mechanicalReduction>1</mechanicalReduction>
    </actuator>
    <joint name="RTseg9_RTseg10_joint">
      <hardwareInterface>hardware_interface/EffortJointInterface</hardwareInterface>
    </joint>
  </transmission>
  <gazebo reference="RTseg9_RTseg10_joint">
    <mu1 value="200.0"/>
    <mu2 value="100.0"/>
    <kp value="10000000.0"/>
    <kd value="1.0"/>
    <material>Gazebo/Grey</material>
  </gazebo>
  <link name="RTseg11">
    <visual>
      <geometry>
        <box size="0.0116666666667 0.0116666666667 0.0125"/>
      </geometry>
      <origin xyz="0 0 0"/>
      <material name="white"/>
    </visual>
    <inertial>
      <mass value="0.01"/>
      <origin rpy="0 0 0" xyz="0 0 0"/>
      <inertia ixx="2.43634161806e-07" ixy="0.0" ixz="0.0" iyy="2.43634161806e-07" iyz="0.0" izz="2.26851761112e-07"/>
    </inertial>
    <!--
		<inertial>
			<mass value="0.001"/>
			<inertia ixx="0.000000001" ixy="0.000000001" ixz="0.000000001" iyy="0.000000001" iyz="0.000000001" izz="0.000000001"/>
		</inertial>
		-->
    <collision>
      <geometry>
        <box size="0.0116666666667 0.0116666666667 0.0125"/>
      </geometry>
      <origin xyz="0 0 0"/>
    </collision>
  </link>
  <gazebo reference="RTseg11">
    <!--plugin name='main_description' filename='libmain_description.so'/>-->
    <mu1>20000</mu1>
    <mu2>20000</mu2>
    <selfCollide>true</selfCollide>
    <gravity>true</gravity>
  </gazebo>
  <joint name="RTseg10_RTseg11_joint" type="revolute">
    <axis xyz="1 0 0"/>
    <limit effort="2.0" lower="-2" upper="2" velocity="0.001"/>
    <dynamics damping="0.02" friction="0.0"/>
    <origin rpy="0 0 0" xyz="0 0 0.0125"/>
    <parent link="RTseg10"/>
    <child link="RTseg11"/>
  </joint>
  <gazebo reference="RTseg10_RTseg11_joint">
    <implicitSpringDamper>True</implicitSpringDamper>
  </gazebo>
  <transmission name="RTseg10_RTseg11_trans">
    <type>transmission_interface/SimpleTransmission</type>
    <actuator name="RTseg10_RTseg11_motor">
      <mechanicalReduction>1</mechanicalReduction>
    </actuator>
    <joint name="RTseg10_RTseg11_joint">
      <hardwareInterface>hardware_interface/EffortJointInterface</hardwareInterface>
    </joint>
  </transmission>
  <gazebo reference="RTseg10_RTseg11_joint">
    <mu1 value="200.0"/>
    <mu2 value="100.0"/>
    <kp value="10000000.0"/>
    <kd value="1.0"/>
    <material>Gazebo/Grey</material>
  </gazebo>
  <link name="RTseg12">
    <visual>
      <geometry>
        <box size="0.0108333333333 0.0108333333333 0.0125"/>
      </geometry>
      <origin xyz="0 0 0"/>
      <material name="white"/>
    </visual>
    <inertial>
      <mass value="0.01"/>
      <origin rpy="0 0 0" xyz="0 0 0"/>
      <inertia ixx="2.28009168055e-07" ixy="0.0" ixz="0.0" iyy="2.28009168055e-07" iyz="0.0" izz="1.9560177361e-07"/>
    </inertial>
    <!--
		<inertial>
			<mass value="0.001"/>
			<inertia ixx="0.000000001" ixy="0.000000001" ixz="0.000000001" iyy="0.000000001" iyz="0.000000001" izz="0.000000001"/>
		</inertial>
		-->
    <collision>
      <geometry>
        <box size="0.0108333333333 0.0108333333333 0.0125"/>
      </geometry>
      <origin xyz="0 0 0"/>
    </collision>
  </link>
  <gazebo reference="RTseg12">
    <!--plugin name='main_description' filename='libmain_description.so'/>-->
    <mu1>20000</mu1>
    <mu2>20000</mu2>
    <selfCollide>true</selfCollide>
    <gravity>true</gravity>
  </gazebo>
  <joint name="RTseg11_RTseg12_joint" type="revolute">
    <axis xyz="1 0 0"/>
    <limit effort="2.0" lower="-2" upper="2" velocity="0.001"/>
    <dynamics damping="0.02" friction="0.0"/>
    <origin rpy="0 0 0" xyz="0 0 0.0125"/>
    <parent link="RTseg11"/>
    <child link="RTseg12"/>
  </joint>
  <gazebo reference="RTseg11_RTseg12_joint">
    <implicitSpringDamper>True</implicitSpringDamper>
  </gazebo>
  <transmission name="RTseg11_RTseg12_trans">
    <type>transmission_interface/SimpleTransmission</type>
    <actuator name="RTseg11_RTseg12_motor">
      <mechanicalReduction>1</mechanicalReduction>
    </actuator>
    <joint name="RTseg11_RTseg12_joint">
      <hardwareInterface>hardware_interface/EffortJointInterface</hardwareInterface>
    </joint>
  </transmission>
  <gazebo reference="RTseg11_RTseg12_joint">
    <mu1 value="200.0"/>
    <mu2 value="100.0"/>
    <kp value="10000000.0"/>
    <kd value="1.0"/>
    <material>Gazebo/Grey</material>
  </gazebo>
  <!--  MACROS FOR FINGER: LB-->
  <link name="LBseg1">
    <visual>
      <geometry>
        <box size="0.02 0.02 0.0125"/>
      </geometry>
      <origin xyz="0 0 0"/>
      <material name="white"/>
    </visual>
    <inertial>
      <mass value="0.01"/>
      <origin rpy="0 0 0" xyz="0 0 0"/>
      <inertia ixx="4.6354148125e-07" ixy="0.0" ixz="0.0" iyy="4.6354148125e-07" iyz="0.0" izz="6.666664e-07"/>
    </inertial>
    <!--
		<inertial>
			<mass value="0.001"/>
			<inertia ixx="0.000000001" ixy="0.000000001" ixz="0.000000001" iyy="0.000000001" iyz="0.000000001" izz="0.000000001"/>
		</inertial>
		-->
    <collision>
      <geometry>
        <box size="0.02 0.02 0.0125"/>
      </geometry>
      <origin xyz="0 0 0"/>
    </collision>
  </link>
  <gazebo reference="LBseg1">
    <!--plugin name='main_description' filename='libmain_description.so'/>-->
    <mu1>20000</mu1>
    <mu2>20000</mu2>
    <selfCollide>true</selfCollide>
    <gravity>true</gravity>
  </gazebo>
  <joint name="palm_LBseg1_joint" type="revolute">
    <axis xyz="1 0 0"/>
    <limit effort="2.0" lower="-0.0" upper="0.0" velocity="0.0001"/>
    <!--<dynamics damping="0.05" friction="0.0"/>-->
    <origin rpy="-0.3 0 0" xyz="-0.04 0.04 0.03"/>
    <parent link="palm"/>
    <child link="LBseg1"/>
  </joint>
  <transmission name="palm_LBseg1_trans">
    <type>transmission_interface/SimpleTransmission</type>
    <actuator name="palm_LBseg1_motor">
      <mechanicalReduction>1</mechanicalReduction>
    </actuator>
    <joint name="palm_LBseg1_joint">
      <hardwareInterface>hardware_interface/EffortJointInterface</hardwareInterface>
    </joint>
  </transmission>
  <gazebo reference="palm_LBseg1_joint">
    <mu1 value="200.0"/>
    <mu2 value="100.0"/>
    <kp value="10000000.0"/>
    <kd value="1.0"/>
    <material>Gazebo/Grey</material>
  </gazebo>
  <link name="LBseg2">
    <visual>
      <geometry>
        <box size="0.0191666666667 0.0191666666667 0.0125"/>
      </geometry>
      <origin xyz="0 0 0"/>
      <material name="white"/>
    </visual>
    <inertial>
      <mass value="0.01"/>
      <origin rpy="0 0 0" xyz="0 0 0"/>
      <inertia ixx="4.36342418057e-07" ixy="0.0" ixz="0.0" iyy="4.36342418057e-07" iyz="0.0" izz="6.12268273613e-07"/>
    </inertial>
    <!--
		<inertial>
			<mass value="0.001"/>
			<inertia ixx="0.000000001" ixy="0.000000001" ixz="0.000000001" iyy="0.000000001" iyz="0.000000001" izz="0.000000001"/>
		</inertial>
		-->
    <collision>
      <geometry>
        <box size="0.0191666666667 0.0191666666667 0.0125"/>
      </geometry>
      <origin xyz="0 0 0"/>
    </collision>
  </link>
  <gazebo reference="LBseg2">
    <!--plugin name='main_description' filename='libmain_description.so'/>-->
    <mu1>20000</mu1>
    <mu2>20000</mu2>
    <selfCollide>true</selfCollide>
    <gravity>true</gravity>
  </gazebo>
  <joint name="LBseg1_LBseg2_joint" type="revolute">
    <axis xyz="1 0 0"/>
    <limit effort="2.0" lower="-2" upper="2" velocity="0.001"/>
    <dynamics damping="0.02" friction="0.0"/>
    <origin rpy="0 0 0" xyz="0 0 0.0125"/>
    <parent link="LBseg1"/>
    <child link="LBseg2"/>
  </joint>
  <gazebo reference="LBseg1_LBseg2_joint">
    <implicitSpringDamper>True</implicitSpringDamper>
  </gazebo>
  <transmission name="LBseg1_LBseg2_trans">
    <type>transmission_interface/SimpleTransmission</type>
    <actuator name="LBseg1_LBseg2_motor">
      <mechanicalReduction>1</mechanicalReduction>
    </actuator>
    <joint name="LBseg1_LBseg2_joint">
      <hardwareInterface>hardware_interface/EffortJointInterface</hardwareInterface>
    </joint>
  </transmission>
  <gazebo reference="LBseg1_LBseg2_joint">
    <mu1 value="200.0"/>
    <mu2 value="100.0"/>
    <kp value="10000000.0"/>
    <kd value="1.0"/>
    <material>Gazebo/Grey</material>
  </gazebo>
  <link name="LBseg3">
    <visual>
      <geometry>
        <box size="0.0183333333333 0.0183333333333 0.0125"/>
      </geometry>
      <origin xyz="0 0 0"/>
      <material name="white"/>
    </visual>
    <inertial>
      <mass value="0.01"/>
      <origin rpy="0 0 0" xyz="0 0 0"/>
      <inertia ixx="4.10300761805e-07" ixy="0.0" ixz="0.0" iyy="4.10300761805e-07" iyz="0.0" izz="5.60184961109e-07"/>
    </inertial>
    <!--
		<inertial>
			<mass value="0.001"/>
			<inertia ixx="0.000000001" ixy="0.000000001" ixz="0.000000001" iyy="0.000000001" iyz="0.000000001" izz="0.000000001"/>
		</inertial>
		-->
    <collision>
      <geometry>
        <box size="0.0183333333333 0.0183333333333 0.0125"/>
      </geometry>
      <origin xyz="0 0 0"/>
    </collision>
  </link>
  <gazebo reference="LBseg3">
    <!--plugin name='main_description' filename='libmain_description.so'/>-->
    <mu1>20000</mu1>
    <mu2>20000</mu2>
    <selfCollide>true</selfCollide>
    <gravity>true</gravity>
  </gazebo>
  <joint name="LBseg2_LBseg3_joint" type="revolute">
    <axis xyz="1 0 0"/>
    <limit effort="2.0" lower="-2" upper="2" velocity="0.001"/>
    <dynamics damping="0.02" friction="0.0"/>
    <origin rpy="0 0 0" xyz="0 0 0.0125"/>
    <parent link="LBseg2"/>
    <child link="LBseg3"/>
  </joint>
  <gazebo reference="LBseg2_LBseg3_joint">
    <implicitSpringDamper>True</implicitSpringDamper>
  </gazebo>
  <transmission name="LBseg2_LBseg3_trans">
    <type>transmission_interface/SimpleTransmission</type>
    <actuator name="LBseg2_LBseg3_motor">
      <mechanicalReduction>1</mechanicalReduction>
    </actuator>
    <joint name="LBseg2_LBseg3_joint">
      <hardwareInterface>hardware_interface/EffortJointInterface</hardwareInterface>
    </joint>
  </transmission>
  <gazebo reference="LBseg2_LBseg3_joint">
    <mu1 value="200.0"/>
    <mu2 value="100.0"/>
    <kp value="10000000.0"/>
    <kd value="1.0"/>
    <material>Gazebo/Grey</material>
  </gazebo>
  <link name="LBseg4">
    <visual>
      <geometry>
        <box size="0.0175 0.0175 0.0125"/>
      </geometry>
      <origin xyz="0 0 0"/>
      <material name="white"/>
    </visual>
    <inertial>
      <mass value="0.01"/>
      <origin rpy="0 0 0" xyz="0 0 0"/>
      <inertia ixx="3.854165125e-07" ixy="0.0" ixz="0.0" iyy="3.854165125e-07" iyz="0.0" izz="5.104164625e-07"/>
    </inertial>
    <!--
		<inertial>
			<mass value="0.001"/>
			<inertia ixx="0.000000001" ixy="0.000000001" ixz="0.000000001" iyy="0.000000001" iyz="0.000000001" izz="0.000000001"/>
		</inertial>
		-->
    <collision>
      <geometry>
        <box size="0.0175 0.0175 0.0125"/>
      </geometry>
      <origin xyz="0 0 0"/>
    </collision>
  </link>
  <gazebo reference="LBseg4">
    <!--plugin name='main_description' filename='libmain_description.so'/>-->
    <mu1>20000</mu1>
    <mu2>20000</mu2>
    <selfCollide>true</selfCollide>
    <gravity>true</gravity>
  </gazebo>
  <joint name="LBseg3_LBseg4_joint" type="revolute">
    <axis xyz="1 0 0"/>
    <limit effort="2.0" lower="-2" upper="2" velocity="0.001"/>
    <dynamics damping="0.02" friction="0.0"/>
    <origin rpy="0 0 0" xyz="0 0 0.0125"/>
    <parent link="LBseg3"/>
    <child link="LBseg4"/>
  </joint>
  <gazebo reference="LBseg3_LBseg4_joint">
    <implicitSpringDamper>True</implicitSpringDamper>
  </gazebo>
  <transmission name="LBseg3_LBseg4_trans">
    <type>transmission_interface/SimpleTransmission</type>
    <actuator name="LBseg3_LBseg4_motor">
      <mechanicalReduction>1</mechanicalReduction>
    </actuator>
    <joint name="LBseg3_LBseg4_joint">
      <hardwareInterface>hardware_interface/EffortJointInterface</hardwareInterface>
    </joint>
  </transmission>
  <gazebo reference="LBseg3_LBseg4_joint">
    <mu1 value="200.0"/>
    <mu2 value="100.0"/>
    <kp value="10000000.0"/>
    <kd value="1.0"/>
    <material>Gazebo/Grey</material>
  </gazebo>
  <link name="LBseg5">
    <visual>
      <geometry>
        <box size="0.0166666666667 0.0166666666667 0.0125"/>
      </geometry>
      <origin xyz="0 0 0"/>
      <material name="white"/>
    </visual>
    <inertial>
      <mass value="0.01"/>
      <origin rpy="0 0 0" xyz="0 0 0"/>
      <inertia ixx="3.6168967014e-07" ixy="0.0" ixz="0.0" iyy="3.6168967014e-07" iyz="0.0" izz="4.6296277778e-07"/>
    </inertial>
    <!--
		<inertial>
			<mass value="0.001"/>
			<inertia ixx="0.000000001" ixy="0.000000001" ixz="0.000000001" iyy="0.000000001" iyz="0.000000001" izz="0.000000001"/>
		</inertial>
		-->
    <collision>
      <geometry>
        <box size="0.0166666666667 0.0166666666667 0.0125"/>
      </geometry>
      <origin xyz="0 0 0"/>
    </collision>
  </link>
  <gazebo reference="LBseg5">
    <!--plugin name='main_description' filename='libmain_description.so'/>-->
    <mu1>20000</mu1>
    <mu2>20000</mu2>
    <selfCollide>true</selfCollide>
    <gravity>true</gravity>
  </gazebo>
  <joint name="LBseg4_LBseg5_joint" type="revolute">
    <axis xyz="1 0 0"/>
    <limit effort="2.0" lower="-2" upper="2" velocity="0.001"/>
    <dynamics damping="0.02" friction="0.0"/>
    <origin rpy="0 0 0" xyz="0 0 0.0125"/>
    <parent link="LBseg4"/>
    <child link="LBseg5"/>
  </joint>
  <gazebo reference="LBseg4_LBseg5_joint">
    <implicitSpringDamper>True</implicitSpringDamper>
  </gazebo>
  <transmission name="LBseg4_LBseg5_trans">
    <type>transmission_interface/SimpleTransmission</type>
    <actuator name="LBseg4_LBseg5_motor">
      <mechanicalReduction>1</mechanicalReduction>
    </actuator>
    <joint name="LBseg4_LBseg5_joint">
      <hardwareInterface>hardware_interface/EffortJointInterface</hardwareInterface>
    </joint>
  </transmission>
  <gazebo reference="LBseg4_LBseg5_joint">
    <mu1 value="200.0"/>
    <mu2 value="100.0"/>
    <kp value="10000000.0"/>
    <kd value="1.0"/>
    <material>Gazebo/Grey</material>
  </gazebo>
  <link name="LBseg6">
    <visual>
      <geometry>
        <box size="0.0158333333333 0.0158333333333 0.0125"/>
      </geometry>
      <origin xyz="0 0 0"/>
      <material name="white"/>
    </visual>
    <inertial>
      <mass value="0.01"/>
      <origin rpy="0 0 0" xyz="0 0 0"/>
      <inertia ixx="3.39120234721e-07" ixy="0.0" ixz="0.0" iyy="3.39120234721e-07" iyz="0.0" izz="4.17823906943e-07"/>
    </inertial>
    <!--
		<inertial>
			<mass value="0.001"/>
			<inertia ixx="0.000000001" ixy="0.000000001" ixz="0.000000001" iyy="0.000000001" iyz="0.000000001" izz="0.000000001"/>
		</inertial>
		-->
    <collision>
      <geometry>
        <box size="0.0158333333333 0.0158333333333 0.0125"/>
      </geometry>
      <origin xyz="0 0 0"/>
    </collision>
  </link>
  <gazebo reference="LBseg6">
    <!--plugin name='main_description' filename='libmain_description.so'/>-->
    <mu1>20000</mu1>
    <mu2>20000</mu2>
    <selfCollide>true</selfCollide>
    <gravity>true</gravity>
  </gazebo>
  <joint name="LBseg5_LBseg6_joint" type="revolute">
    <axis xyz="1 0 0"/>
    <limit effort="2.0" lower="-2" upper="2" velocity="0.001"/>
    <dynamics damping="0.02" friction="0.0"/>
    <origin rpy="0 0 0" xyz="0 0 0.0125"/>
    <parent link="LBseg5"/>
    <child link="LBseg6"/>
  </joint>
  <gazebo reference="LBseg5_LBseg6_joint">
    <implicitSpringDamper>True</implicitSpringDamper>
  </gazebo>
  <transmission name="LBseg5_LBseg6_trans">
    <type>transmission_interface/SimpleTransmission</type>
    <actuator name="LBseg5_LBseg6_motor">
      <mechanicalReduction>1</mechanicalReduction>
    </actuator>
    <joint name="LBseg5_LBseg6_joint">
      <hardwareInterface>hardware_interface/EffortJointInterface</hardwareInterface>
    </joint>
  </transmission>
  <gazebo reference="LBseg5_LBseg6_joint">
    <mu1 value="200.0"/>
    <mu2 value="100.0"/>
    <kp value="10000000.0"/>
    <kd value="1.0"/>
    <material>Gazebo/Grey</material>
  </gazebo>
  <link name="LBseg7">
    <visual>
      <geometry>
        <box size="0.015 0.015 0.0125"/>
      </geometry>
      <origin xyz="0 0 0"/>
      <material name="white"/>
    </visual>
    <inertial>
      <mass value="0.01"/>
      <origin rpy="0 0 0" xyz="0 0 0"/>
      <inertia ixx="3.1770820625e-07" ixy="0.0" ixz="0.0" iyy="3.1770820625e-07" iyz="0.0" izz="3.7499985e-07"/>
    </inertial>
    <!--
		<inertial>
			<mass value="0.001"/>
			<inertia ixx="0.000000001" ixy="0.000000001" ixz="0.000000001" iyy="0.000000001" iyz="0.000000001" izz="0.000000001"/>
		</inertial>
		-->
    <collision>
      <geometry>
        <box size="0.015 0.015 0.0125"/>
      </geometry>
      <origin xyz="0 0 0"/>
    </collision>
  </link>
  <gazebo reference="LBseg7">
    <!--plugin name='main_description' filename='libmain_description.so'/>-->
    <mu1>20000</mu1>
    <mu2>20000</mu2>
    <selfCollide>true</selfCollide>
    <gravity>true</gravity>
  </gazebo>
  <joint name="LBseg6_LBseg7_joint" type="revolute">
    <axis xyz="1 0 0"/>
    <limit effort="2.0" lower="-2" upper="2" velocity="0.001"/>
    <dynamics damping="0.02" friction="0.0"/>
    <origin rpy="0 0 0" xyz="0 0 0.0125"/>
    <parent link="LBseg6"/>
    <child link="LBseg7"/>
  </joint>
  <gazebo reference="LBseg6_LBseg7_joint">
    <implicitSpringDamper>True</implicitSpringDamper>
  </gazebo>
  <transmission name="LBseg6_LBseg7_trans">
    <type>transmission_interface/SimpleTransmission</type>
    <actuator name="LBseg6_LBseg7_motor">
      <mechanicalReduction>1</mechanicalReduction>
    </actuator>
    <joint name="LBseg6_LBseg7_joint">
      <hardwareInterface>hardware_interface/EffortJointInterface</hardwareInterface>
    </joint>
  </transmission>
  <gazebo reference="LBseg6_LBseg7_joint">
    <mu1 value="200.0"/>
    <mu2 value="100.0"/>
    <kp value="10000000.0"/>
    <kd value="1.0"/>
    <material>Gazebo/Grey</material>
  </gazebo>
  <link name="LBseg8">
    <visual>
      <geometry>
        <box size="0.0141666666667 0.0141666666667 0.0125"/>
      </geometry>
      <origin xyz="0 0 0"/>
      <material name="white"/>
    </visual>
    <inertial>
      <mass value="0.01"/>
      <origin rpy="0 0 0" xyz="0 0 0"/>
      <inertia ixx="2.97453584723e-07" ixy="0.0" ixz="0.0" iyy="2.97453584723e-07" iyz="0.0" izz="3.34490606946e-07"/>
    </inertial>
    <!--
		<inertial>
			<mass value="0.001"/>
			<inertia ixx="0.000000001" ixy="0.000000001" ixz="0.000000001" iyy="0.000000001" iyz="0.000000001" izz="0.000000001"/>
		</inertial>
		-->
    <collision>
      <geometry>
        <box size="0.0141666666667 0.0141666666667 0.0125"/>
      </geometry>
      <origin xyz="0 0 0"/>
    </collision>
  </link>
  <gazebo reference="LBseg8">
    <!--plugin name='main_description' filename='libmain_description.so'/>-->
    <mu1>20000</mu1>
    <mu2>20000</mu2>
    <selfCollide>true</selfCollide>
    <gravity>true</gravity>
  </gazebo>
  <joint name="LBseg7_LBseg8_joint" type="revolute">
    <axis xyz="1 0 0"/>
    <limit effort="2.0" lower="-2" upper="2" velocity="0.001"/>
    <dynamics damping="0.02" friction="0.0"/>
    <origin rpy="0 0 0" xyz="0 0 0.0125"/>
    <parent link="LBseg7"/>
    <child link="LBseg8"/>
  </joint>
  <gazebo reference="LBseg7_LBseg8_joint">
    <implicitSpringDamper>True</implicitSpringDamper>
  </gazebo>
  <transmission name="LBseg7_LBseg8_trans">
    <type>transmission_interface/SimpleTransmission</type>
    <actuator name="LBseg7_LBseg8_motor">
      <mechanicalReduction>1</mechanicalReduction>
    </actuator>
    <joint name="LBseg7_LBseg8_joint">
      <hardwareInterface>hardware_interface/EffortJointInterface</hardwareInterface>
    </joint>
  </transmission>
  <gazebo reference="LBseg7_LBseg8_joint">
    <mu1 value="200.0"/>
    <mu2 value="100.0"/>
    <kp value="10000000.0"/>
    <kd value="1.0"/>
    <material>Gazebo/Grey</material>
  </gazebo>
  <link name="LBseg9">
    <visual>
      <geometry>
        <box size="0.0133333333333 0.0133333333333 0.0125"/>
      </geometry>
      <origin xyz="0 0 0"/>
      <material name="white"/>
    </visual>
    <inertial>
      <mass value="0.01"/>
      <origin rpy="0 0 0" xyz="0 0 0"/>
      <inertia ixx="2.78356370138e-07" ixy="0.0" ixz="0.0" iyy="2.78356370138e-07" iyz="0.0" izz="2.96296177776e-07"/>
    </inertial>
    <!--
		<inertial>
			<mass value="0.001"/>
			<inertia ixx="0.000000001" ixy="0.000000001" ixz="0.000000001" iyy="0.000000001" iyz="0.000000001" izz="0.000000001"/>
		</inertial>
		-->
    <collision>
      <geometry>
        <box size="0.0133333333333 0.0133333333333 0.0125"/>
      </geometry>
      <origin xyz="0 0 0"/>
    </collision>
  </link>
  <gazebo reference="LBseg9">
    <!--plugin name='main_description' filename='libmain_description.so'/>-->
    <mu1>20000</mu1>
    <mu2>20000</mu2>
    <selfCollide>true</selfCollide>
    <gravity>true</gravity>
  </gazebo>
  <joint name="LBseg8_LBseg9_joint" type="revolute">
    <axis xyz="1 0 0"/>
    <limit effort="2.0" lower="-2" upper="2" velocity="0.001"/>
    <dynamics damping="0.02" friction="0.0"/>
    <origin rpy="0 0 0" xyz="0 0 0.0125"/>
    <parent link="LBseg8"/>
    <child link="LBseg9"/>
  </joint>
  <gazebo reference="LBseg8_LBseg9_joint">
    <implicitSpringDamper>True</implicitSpringDamper>
  </gazebo>
  <transmission name="LBseg8_LBseg9_trans">
    <type>transmission_interface/SimpleTransmission</type>
    <actuator name="LBseg8_LBseg9_motor">
      <mechanicalReduction>1</mechanicalReduction>
    </actuator>
    <joint name="LBseg8_LBseg9_joint">
      <hardwareInterface>hardware_interface/EffortJointInterface</hardwareInterface>
    </joint>
  </transmission>
  <gazebo reference="LBseg8_LBseg9_joint">
    <mu1 value="200.0"/>
    <mu2 value="100.0"/>
    <kp value="10000000.0"/>
    <kd value="1.0"/>
    <material>Gazebo/Grey</material>
  </gazebo>
  <link name="LBseg10">
    <visual>
      <geometry>
        <box size="0.0125 0.0125 0.0125"/>
      </geometry>
      <origin xyz="0 0 0"/>
      <material name="white"/>
    </visual>
    <inertial>
      <mass value="0.01"/>
      <origin rpy="0 0 0" xyz="0 0 0"/>
      <inertia ixx="2.604165625e-07" ixy="0.0" ixz="0.0" iyy="2.604165625e-07" iyz="0.0" izz="2.604165625e-07"/>
    </inertial>
    <!--
		<inertial>
			<mass value="0.001"/>
			<inertia ixx="0.000000001" ixy="0.000000001" ixz="0.000000001" iyy="0.000000001" iyz="0.000000001" izz="0.000000001"/>
		</inertial>
		-->
    <collision>
      <geometry>
        <box size="0.0125 0.0125 0.0125"/>
      </geometry>
      <origin xyz="0 0 0"/>
    </collision>
  </link>
  <gazebo reference="LBseg10">
    <!--plugin name='main_description' filename='libmain_description.so'/>-->
    <mu1>20000</mu1>
    <mu2>20000</mu2>
    <selfCollide>true</selfCollide>
    <gravity>true</gravity>
  </gazebo>
  <joint name="LBseg9_LBseg10_joint" type="revolute">
    <axis xyz="1 0 0"/>
    <limit effort="2.0" lower="-2" upper="2" velocity="0.001"/>
    <dynamics damping="0.02" friction="0.0"/>
    <origin rpy="0 0 0" xyz="0 0 0.0125"/>
    <parent link="LBseg9"/>
    <child link="LBseg10"/>
  </joint>
  <gazebo reference="LBseg9_LBseg10_joint">
    <implicitSpringDamper>True</implicitSpringDamper>
  </gazebo>
  <transmission name="LBseg9_LBseg10_trans">
    <type>transmission_interface/SimpleTransmission</type>
    <actuator name="LBseg9_LBseg10_motor">
      <mechanicalReduction>1</mechanicalReduction>
    </actuator>
    <joint name="LBseg9_LBseg10_joint">
      <hardwareInterface>hardware_interface/EffortJointInterface</hardwareInterface>
    </joint>
  </transmission>
  <gazebo reference="LBseg9_LBseg10_joint">
    <mu1 value="200.0"/>
    <mu2 value="100.0"/>
    <kp value="10000000.0"/>
    <kd value="1.0"/>
    <material>Gazebo/Grey</material>
  </gazebo>
  <link name="LBseg11">
    <visual>
      <geometry>
        <box size="0.0116666666667 0.0116666666667 0.0125"/>
      </geometry>
      <origin xyz="0 0 0"/>
      <material name="white"/>
    </visual>
    <inertial>
      <mass value="0.01"/>
      <origin rpy="0 0 0" xyz="0 0 0"/>
      <inertia ixx="2.43634161806e-07" ixy="0.0" ixz="0.0" iyy="2.43634161806e-07" iyz="0.0" izz="2.26851761112e-07"/>
    </inertial>
    <!--
		<inertial>
			<mass value="0.001"/>
			<inertia ixx="0.000000001" ixy="0.000000001" ixz="0.000000001" iyy="0.000000001" iyz="0.000000001" izz="0.000000001"/>
		</inertial>
		-->
    <collision>
      <geometry>
        <box size="0.0116666666667 0.0116666666667 0.0125"/>
      </geometry>
      <origin xyz="0 0 0"/>
    </collision>
  </link>
  <gazebo reference="LBseg11">
    <!--plugin name='main_description' filename='libmain_description.so'/>-->
    <mu1>20000</mu1>
    <mu2>20000</mu2>
    <selfCollide>true</selfCollide>
    <gravity>true</gravity>
  </gazebo>
  <joint name="LBseg10_LBseg11_joint" type="revolute">
    <axis xyz="1 0 0"/>
    <limit effort="2.0" lower="-2" upper="2" velocity="0.001"/>
    <dynamics damping="0.02" friction="0.0"/>
    <origin rpy="0 0 0" xyz="0 0 0.0125"/>
    <parent link="LBseg10"/>
    <child link="LBseg11"/>
  </joint>
  <gazebo reference="LBseg10_LBseg11_joint">
    <implicitSpringDamper>True</implicitSpringDamper>
  </gazebo>
  <transmission name="LBseg10_LBseg11_trans">
    <type>transmission_interface/SimpleTransmission</type>
    <actuator name="LBseg10_LBseg11_motor">
      <mechanicalReduction>1</mechanicalReduction>
    </actuator>
    <joint name="LBseg10_LBseg11_joint">
      <hardwareInterface>hardware_interface/EffortJointInterface</hardwareInterface>
    </joint>
  </transmission>
  <gazebo reference="LBseg10_LBseg11_joint">
    <mu1 value="200.0"/>
    <mu2 value="100.0"/>
    <kp value="10000000.0"/>
    <kd value="1.0"/>
    <material>Gazebo/Grey</material>
  </gazebo>
  <link name="LBseg12">
    <visual>
      <geometry>
        <box size="0.0108333333333 0.0108333333333 0.0125"/>
      </geometry>
      <origin xyz="0 0 0"/>
      <material name="white"/>
    </visual>
    <inertial>
      <mass value="0.01"/>
      <origin rpy="0 0 0" xyz="0 0 0"/>
      <inertia ixx="2.28009168055e-07" ixy="0.0" ixz="0.0" iyy="2.28009168055e-07" iyz="0.0" izz="1.9560177361e-07"/>
    </inertial>
    <!--
		<inertial>
			<mass value="0.001"/>
			<inertia ixx="0.000000001" ixy="0.000000001" ixz="0.000000001" iyy="0.000000001" iyz="0.000000001" izz="0.000000001"/>
		</inertial>
		-->
    <collision>
      <geometry>
        <box size="0.0108333333333 0.0108333333333 0.0125"/>
      </geometry>
      <origin xyz="0 0 0"/>
    </collision>
  </link>
  <gazebo reference="LBseg12">
    <!--plugin name='main_description' filename='libmain_description.so'/>-->
    <mu1>20000</mu1>
    <mu2>20000</mu2>
    <selfCollide>true</selfCollide>
    <gravity>true</gravity>
  </gazebo>
  <joint name="LBseg11_LBseg12_joint" type="revolute">
    <axis xyz="1 0 0"/>
    <limit effort="2.0" lower="-2" upper="2" velocity="0.001"/>
    <dynamics damping="0.02" friction="0.0"/>
    <origin rpy="0 0 0" xyz="0 0 0.0125"/>
    <parent link="LBseg11"/>
    <child link="LBseg12"/>
  </joint>
  <gazebo reference="LBseg11_LBseg12_joint">
    <implicitSpringDamper>True</implicitSpringDamper>
  </gazebo>
  <transmission name="LBseg11_LBseg12_trans">
    <type>transmission_interface/SimpleTransmission</type>
    <actuator name="LBseg11_LBseg12_motor">
      <mechanicalReduction>1</mechanicalReduction>
    </actuator>
    <joint name="LBseg11_LBseg12_joint">
      <hardwareInterface>hardware_interface/EffortJointInterface</hardwareInterface>
    </joint>
  </transmission>
  <gazebo reference="LBseg11_LBseg12_joint">
    <mu1 value="200.0"/>
    <mu2 value="100.0"/>
    <kp value="10000000.0"/>
    <kd value="1.0"/>
    <material>Gazebo/Grey</material>
  </gazebo>
  <!--  MACROS FOR FINGER: RB-->
  <link name="RBseg1">
    <visual>
      <geometry>
        <box size="0.02 0.02 0.0125"/>
      </geometry>
      <origin xyz="0 0 0"/>
      <material name="white"/>
    </visual>
    <inertial>
      <mass value="0.01"/>
      <origin rpy="0 0 0" xyz="0 0 0"/>
      <inertia ixx="4.6354148125e-07" ixy="0.0" ixz="0.0" iyy="4.6354148125e-07" iyz="0.0" izz="6.666664e-07"/>
    </inertial>
    <!--
		<inertial>
			<mass value="0.001"/>
			<inertia ixx="0.000000001" ixy="0.000000001" ixz="0.000000001" iyy="0.000000001" iyz="0.000000001" izz="0.000000001"/>
		</inertial>
		-->
    <collision>
      <geometry>
        <box size="0.02 0.02 0.0125"/>
      </geometry>
      <origin xyz="0 0 0"/>
    </collision>
  </link>
  <gazebo reference="RBseg1">
    <!--plugin name='main_description' filename='libmain_description.so'/>-->
    <mu1>20000</mu1>
    <mu2>20000</mu2>
    <selfCollide>true</selfCollide>
    <gravity>true</gravity>
  </gazebo>
  <joint name="palm_RBseg1_joint" type="revolute">
    <axis xyz="1 0 0"/>
    <limit effort="2.0" lower="-0.0" upper="0.0" velocity="0.0001"/>
    <!--<dynamics damping="0.05" friction="0.0"/>-->
    <origin rpy="-0.3 0 3.14159" xyz="-0.04 -0.04 0.03"/>
    <parent link="palm"/>
    <child link="RBseg1"/>
  </joint>
  <transmission name="palm_RBseg1_trans">
    <type>transmission_interface/SimpleTransmission</type>
    <actuator name="palm_RBseg1_motor">
      <mechanicalReduction>1</mechanicalReduction>
    </actuator>
    <joint name="palm_RBseg1_joint">
      <hardwareInterface>hardware_interface/EffortJointInterface</hardwareInterface>
    </joint>
  </transmission>
  <gazebo reference="palm_RBseg1_joint">
    <mu1 value="200.0"/>
    <mu2 value="100.0"/>
    <kp value="10000000.0"/>
    <kd value="1.0"/>
    <material>Gazebo/Grey</material>
  </gazebo>
  <link name="RBseg2">
    <visual>
      <geometry>
        <box size="0.0191666666667 0.0191666666667 0.0125"/>
      </geometry>
      <origin xyz="0 0 0"/>
      <material name="white"/>
    </visual>
    <inertial>
      <mass value="0.01"/>
      <origin rpy="0 0 0" xyz="0 0 0"/>
      <inertia ixx="4.36342418057e-07" ixy="0.0" ixz="0.0" iyy="4.36342418057e-07" iyz="0.0" izz="6.12268273613e-07"/>
    </inertial>
    <!--
		<inertial>
			<mass value="0.001"/>
			<inertia ixx="0.000000001" ixy="0.000000001" ixz="0.000000001" iyy="0.000000001" iyz="0.000000001" izz="0.000000001"/>
		</inertial>
		-->
    <collision>
      <geometry>
        <box size="0.0191666666667 0.0191666666667 0.0125"/>
      </geometry>
      <origin xyz="0 0 0"/>
    </collision>
  </link>
  <gazebo reference="RBseg2">
    <!--plugin name='main_description' filename='libmain_description.so'/>-->
    <mu1>20000</mu1>
    <mu2>20000</mu2>
    <selfCollide>true</selfCollide>
    <gravity>true</gravity>
  </gazebo>
  <joint name="RBseg1_RBseg2_joint" type="revolute">
    <axis xyz="1 0 0"/>
    <limit effort="2.0" lower="-2" upper="2" velocity="0.001"/>
    <dynamics damping="0.02" friction="0.0"/>
    <origin rpy="0 0 0" xyz="0 0 0.0125"/>
    <parent link="RBseg1"/>
    <child link="RBseg2"/>
  </joint>
  <gazebo reference="RBseg1_RBseg2_joint">
    <implicitSpringDamper>True</implicitSpringDamper>
  </gazebo>
  <transmission name="RBseg1_RBseg2_trans">
    <type>transmission_interface/SimpleTransmission</type>
    <actuator name="RBseg1_RBseg2_motor">
      <mechanicalReduction>1</mechanicalReduction>
    </actuator>
    <joint name="RBseg1_RBseg2_joint">
      <hardwareInterface>hardware_interface/EffortJointInterface</hardwareInterface>
    </joint>
  </transmission>
  <gazebo reference="RBseg1_RBseg2_joint">
    <mu1 value="200.0"/>
    <mu2 value="100.0"/>
    <kp value="10000000.0"/>
    <kd value="1.0"/>
    <material>Gazebo/Grey</material>
  </gazebo>
  <link name="RBseg3">
    <visual>
      <geometry>
        <box size="0.0183333333333 0.0183333333333 0.0125"/>
      </geometry>
      <origin xyz="0 0 0"/>
      <material name="white"/>
    </visual>
    <inertial>
      <mass value="0.01"/>
      <origin rpy="0 0 0" xyz="0 0 0"/>
      <inertia ixx="4.10300761805e-07" ixy="0.0" ixz="0.0" iyy="4.10300761805e-07" iyz="0.0" izz="5.60184961109e-07"/>
    </inertial>
    <!--
		<inertial>
			<mass value="0.001"/>
			<inertia ixx="0.000000001" ixy="0.000000001" ixz="0.000000001" iyy="0.000000001" iyz="0.000000001" izz="0.000000001"/>
		</inertial>
		-->
    <collision>
      <geometry>
        <box size="0.0183333333333 0.0183333333333 0.0125"/>
      </geometry>
      <origin xyz="0 0 0"/>
    </collision>
  </link>
  <gazebo reference="RBseg3">
    <!--plugin name='main_description' filename='libmain_description.so'/>-->
    <mu1>20000</mu1>
    <mu2>20000</mu2>
    <selfCollide>true</selfCollide>
    <gravity>true</gravity>
  </gazebo>
  <joint name="RBseg2_RBseg3_joint" type="revolute">
    <axis xyz="1 0 0"/>
    <limit effort="2.0" lower="-2" upper="2" velocity="0.001"/>
    <dynamics damping="0.02" friction="0.0"/>
    <origin rpy="0 0 0" xyz="0 0 0.0125"/>
    <parent link="RBseg2"/>
    <child link="RBseg3"/>
  </joint>
  <gazebo reference="RBseg2_RBseg3_joint">
    <implicitSpringDamper>True</implicitSpringDamper>
  </gazebo>
  <transmission name="RBseg2_RBseg3_trans">
    <type>transmission_interface/SimpleTransmission</type>
    <actuator name="RBseg2_RBseg3_motor">
      <mechanicalReduction>1</mechanicalReduction>
    </actuator>
    <joint name="RBseg2_RBseg3_joint">
      <hardwareInterface>hardware_interface/EffortJointInterface</hardwareInterface>
    </joint>
  </transmission>
  <gazebo reference="RBseg2_RBseg3_joint">
    <mu1 value="200.0"/>
    <mu2 value="100.0"/>
    <kp value="10000000.0"/>
    <kd value="1.0"/>
    <material>Gazebo/Grey</material>
  </gazebo>
  <link name="RBseg4">
    <visual>
      <geometry>
        <box size="0.0175 0.0175 0.0125"/>
      </geometry>
      <origin xyz="0 0 0"/>
      <material name="white"/>
    </visual>
    <inertial>
      <mass value="0.01"/>
      <origin rpy="0 0 0" xyz="0 0 0"/>
      <inertia ixx="3.854165125e-07" ixy="0.0" ixz="0.0" iyy="3.854165125e-07" iyz="0.0" izz="5.104164625e-07"/>
    </inertial>
    <!--
		<inertial>
			<mass value="0.001"/>
			<inertia ixx="0.000000001" ixy="0.000000001" ixz="0.000000001" iyy="0.000000001" iyz="0.000000001" izz="0.000000001"/>
		</inertial>
		-->
    <collision>
      <geometry>
        <box size="0.0175 0.0175 0.0125"/>
      </geometry>
      <origin xyz="0 0 0"/>
    </collision>
  </link>
  <gazebo reference="RBseg4">
    <!--plugin name='main_description' filename='libmain_description.so'/>-->
    <mu1>20000</mu1>
    <mu2>20000</mu2>
    <selfCollide>true</selfCollide>
    <gravity>true</gravity>
  </gazebo>
  <joint name="RBseg3_RBseg4_joint" type="revolute">
    <axis xyz="1 0 0"/>
    <limit effort="2.0" lower="-2" upper="2" velocity="0.001"/>
    <dynamics damping="0.02" friction="0.0"/>
    <origin rpy="0 0 0" xyz="0 0 0.0125"/>
    <parent link="RBseg3"/>
    <child link="RBseg4"/>
  </joint>
  <gazebo reference="RBseg3_RBseg4_joint">
    <implicitSpringDamper>True</implicitSpringDamper>
  </gazebo>
  <transmission name="RBseg3_RBseg4_trans">
    <type>transmission_interface/SimpleTransmission</type>
    <actuator name="RBseg3_RBseg4_motor">
      <mechanicalReduction>1</mechanicalReduction>
    </actuator>
    <joint name="RBseg3_RBseg4_joint">
      <hardwareInterface>hardware_interface/EffortJointInterface</hardwareInterface>
    </joint>
  </transmission>
  <gazebo reference="RBseg3_RBseg4_joint">
    <mu1 value="200.0"/>
    <mu2 value="100.0"/>
    <kp value="10000000.0"/>
    <kd value="1.0"/>
    <material>Gazebo/Grey</material>
  </gazebo>
  <link name="RBseg5">
    <visual>
      <geometry>
        <box size="0.0166666666667 0.0166666666667 0.0125"/>
      </geometry>
      <origin xyz="0 0 0"/>
      <material name="white"/>
    </visual>
    <inertial>
      <mass value="0.01"/>
      <origin rpy="0 0 0" xyz="0 0 0"/>
      <inertia ixx="3.6168967014e-07" ixy="0.0" ixz="0.0" iyy="3.6168967014e-07" iyz="0.0" izz="4.6296277778e-07"/>
    </inertial>
    <!--
		<inertial>
			<mass value="0.001"/>
			<inertia ixx="0.000000001" ixy="0.000000001" ixz="0.000000001" iyy="0.000000001" iyz="0.000000001" izz="0.000000001"/>
		</inertial>
		-->
    <collision>
      <geometry>
        <box size="0.0166666666667 0.0166666666667 0.0125"/>
      </geometry>
      <origin xyz="0 0 0"/>
    </collision>
  </link>
  <gazebo reference="RBseg5">
    <!--plugin name='main_description' filename='libmain_description.so'/>-->
    <mu1>20000</mu1>
    <mu2>20000</mu2>
    <selfCollide>true</selfCollide>
    <gravity>true</gravity>
  </gazebo>
  <joint name="RBseg4_RBseg5_joint" type="revolute">
    <axis xyz="1 0 0"/>
    <limit effort="2.0" lower="-2" upper="2" velocity="0.001"/>
    <dynamics damping="0.02" friction="0.0"/>
    <origin rpy="0 0 0" xyz="0 0 0.0125"/>
    <parent link="RBseg4"/>
    <child link="RBseg5"/>
  </joint>
  <gazebo reference="RBseg4_RBseg5_joint">
    <implicitSpringDamper>True</implicitSpringDamper>
  </gazebo>
  <transmission name="RBseg4_RBseg5_trans">
    <type>transmission_interface/SimpleTransmission</type>
    <actuator name="RBseg4_RBseg5_motor">
      <mechanicalReduction>1</mechanicalReduction>
    </actuator>
    <joint name="RBseg4_RBseg5_joint">
      <hardwareInterface>hardware_interface/EffortJointInterface</hardwareInterface>
    </joint>
  </transmission>
  <gazebo reference="RBseg4_RBseg5_joint">
    <mu1 value="200.0"/>
    <mu2 value="100.0"/>
    <kp value="10000000.0"/>
    <kd value="1.0"/>
    <material>Gazebo/Grey</material>
  </gazebo>
  <link name="RBseg6">
    <visual>
      <geometry>
        <box size="0.0158333333333 0.0158333333333 0.0125"/>
      </geometry>
      <origin xyz="0 0 0"/>
      <material name="white"/>
    </visual>
    <inertial>
      <mass value="0.01"/>
      <origin rpy="0 0 0" xyz="0 0 0"/>
      <inertia ixx="3.39120234721e-07" ixy="0.0" ixz="0.0" iyy="3.39120234721e-07" iyz="0.0" izz="4.17823906943e-07"/>
    </inertial>
    <!--
		<inertial>
			<mass value="0.001"/>
			<inertia ixx="0.000000001" ixy="0.000000001" ixz="0.000000001" iyy="0.000000001" iyz="0.000000001" izz="0.000000001"/>
		</inertial>
		-->
    <collision>
      <geometry>
        <box size="0.0158333333333 0.0158333333333 0.0125"/>
      </geometry>
      <origin xyz="0 0 0"/>
    </collision>
  </link>
  <gazebo reference="RBseg6">
    <!--plugin name='main_description' filename='libmain_description.so'/>-->
    <mu1>20000</mu1>
    <mu2>20000</mu2>
    <selfCollide>true</selfCollide>
    <gravity>true</gravity>
  </gazebo>
  <joint name="RBseg5_RBseg6_joint" type="revolute">
    <axis xyz="1 0 0"/>
    <limit effort="2.0" lower="-2" upper="2" velocity="0.001"/>
    <dynamics damping="0.02" friction="0.0"/>
    <origin rpy="0 0 0" xyz="0 0 0.0125"/>
    <parent link="RBseg5"/>
    <child link="RBseg6"/>
  </joint>
  <gazebo reference="RBseg5_RBseg6_joint">
    <implicitSpringDamper>True</implicitSpringDamper>
  </gazebo>
  <transmission name="RBseg5_RBseg6_trans">
    <type>transmission_interface/SimpleTransmission</type>
    <actuator name="RBseg5_RBseg6_motor">
      <mechanicalReduction>1</mechanicalReduction>
    </actuator>
    <joint name="RBseg5_RBseg6_joint">
      <hardwareInterface>hardware_interface/EffortJointInterface</hardwareInterface>
    </joint>
  </transmission>
  <gazebo reference="RBseg5_RBseg6_joint">
    <mu1 value="200.0"/>
    <mu2 value="100.0"/>
    <kp value="10000000.0"/>
    <kd value="1.0"/>
    <material>Gazebo/Grey</material>
  </gazebo>
  <link name="RBseg7">
    <visual>
      <geometry>
        <box size="0.015 0.015 0.0125"/>
      </geometry>
      <origin xyz="0 0 0"/>
      <material name="white"/>
    </visual>
    <inertial>
      <mass value="0.01"/>
      <origin rpy="0 0 0" xyz="0 0 0"/>
      <inertia ixx="3.1770820625e-07" ixy="0.0" ixz="0.0" iyy="3.1770820625e-07" iyz="0.0" izz="3.7499985e-07"/>
    </inertial>
    <!--
		<inertial>
			<mass value="0.001"/>
			<inertia ixx="0.000000001" ixy="0.000000001" ixz="0.000000001" iyy="0.000000001" iyz="0.000000001" izz="0.000000001"/>
		</inertial>
		-->
    <collision>
      <geometry>
        <box size="0.015 0.015 0.0125"/>
      </geometry>
      <origin xyz="0 0 0"/>
    </collision>
  </link>
  <gazebo reference="RBseg7">
    <!--plugin name='main_description' filename='libmain_description.so'/>-->
    <mu1>20000</mu1>
    <mu2>20000</mu2>
    <selfCollide>true</selfCollide>
    <gravity>true</gravity>
  </gazebo>
  <joint name="RBseg6_RBseg7_joint" type="revolute">
    <axis xyz="1 0 0"/>
    <limit effort="2.0" lower="-2" upper="2" velocity="0.001"/>
    <dynamics damping="0.02" friction="0.0"/>
    <origin rpy="0 0 0" xyz="0 0 0.0125"/>
    <parent link="RBseg6"/>
    <child link="RBseg7"/>
  </joint>
  <gazebo reference="RBseg6_RBseg7_joint">
    <implicitSpringDamper>True</implicitSpringDamper>
  </gazebo>
  <transmission name="RBseg6_RBseg7_trans">
    <type>transmission_interface/SimpleTransmission</type>
    <actuator name="RBseg6_RBseg7_motor">
      <mechanicalReduction>1</mechanicalReduction>
    </actuator>
    <joint name="RBseg6_RBseg7_joint">
      <hardwareInterface>hardware_interface/EffortJointInterface</hardwareInterface>
    </joint>
  </transmission>
  <gazebo reference="RBseg6_RBseg7_joint">
    <mu1 value="200.0"/>
    <mu2 value="100.0"/>
    <kp value="10000000.0"/>
    <kd value="1.0"/>
    <material>Gazebo/Grey</material>
  </gazebo>
  <link name="RBseg8">
    <visual>
      <geometry>
        <box size="0.0141666666667 0.0141666666667 0.0125"/>
      </geometry>
      <origin xyz="0 0 0"/>
      <material name="white"/>
    </visual>
    <inertial>
      <mass value="0.01"/>
      <origin rpy="0 0 0" xyz="0 0 0"/>
      <inertia ixx="2.97453584723e-07" ixy="0.0" ixz="0.0" iyy="2.97453584723e-07" iyz="0.0" izz="3.34490606946e-07"/>
    </inertial>
    <!--
		<inertial>
			<mass value="0.001"/>
			<inertia ixx="0.000000001" ixy="0.000000001" ixz="0.000000001" iyy="0.000000001" iyz="0.000000001" izz="0.000000001"/>
		</inertial>
		-->
    <collision>
      <geometry>
        <box size="0.0141666666667 0.0141666666667 0.0125"/>
      </geometry>
      <origin xyz="0 0 0"/>
    </collision>
  </link>
  <gazebo reference="RBseg8">
    <!--plugin name='main_description' filename='libmain_description.so'/>-->
    <mu1>20000</mu1>
    <mu2>20000</mu2>
    <selfCollide>true</selfCollide>
    <gravity>true</gravity>
  </gazebo>
  <joint name="RBseg7_RBseg8_joint" type="revolute">
    <axis xyz="1 0 0"/>
    <limit effort="2.0" lower="-2" upper="2" velocity="0.001"/>
    <dynamics damping="0.02" friction="0.0"/>
    <origin rpy="0 0 0" xyz="0 0 0.0125"/>
    <parent link="RBseg7"/>
    <child link="RBseg8"/>
  </joint>
  <gazebo reference="RBseg7_RBseg8_joint">
    <implicitSpringDamper>True</implicitSpringDamper>
  </gazebo>
  <transmission name="RBseg7_RBseg8_trans">
    <type>transmission_interface/SimpleTransmission</type>
    <actuator name="RBseg7_RBseg8_motor">
      <mechanicalReduction>1</mechanicalReduction>
    </actuator>
    <joint name="RBseg7_RBseg8_joint">
      <hardwareInterface>hardware_interface/EffortJointInterface</hardwareInterface>
    </joint>
  </transmission>
  <gazebo reference="RBseg7_RBseg8_joint">
    <mu1 value="200.0"/>
    <mu2 value="100.0"/>
    <kp value="10000000.0"/>
    <kd value="1.0"/>
    <material>Gazebo/Grey</material>
  </gazebo>
  <link name="RBseg9">
    <visual>
      <geometry>
        <box size="0.0133333333333 0.0133333333333 0.0125"/>
      </geometry>
      <origin xyz="0 0 0"/>
      <material name="white"/>
    </visual>
    <inertial>
      <mass value="0.01"/>
      <origin rpy="0 0 0" xyz="0 0 0"/>
      <inertia ixx="2.78356370138e-07" ixy="0.0" ixz="0.0" iyy="2.78356370138e-07" iyz="0.0" izz="2.96296177776e-07"/>
    </inertial>
    <!--
		<inertial>
			<mass value="0.001"/>
			<inertia ixx="0.000000001" ixy="0.000000001" ixz="0.000000001" iyy="0.000000001" iyz="0.000000001" izz="0.000000001"/>
		</inertial>
		-->
    <collision>
      <geometry>
        <box size="0.0133333333333 0.0133333333333 0.0125"/>
      </geometry>
      <origin xyz="0 0 0"/>
    </collision>
  </link>
  <gazebo reference="RBseg9">
    <!--plugin name='main_description' filename='libmain_description.so'/>-->
    <mu1>20000</mu1>
    <mu2>20000</mu2>
    <selfCollide>true</selfCollide>
    <gravity>true</gravity>
  </gazebo>
  <joint name="RBseg8_RBseg9_joint" type="revolute">
    <axis xyz="1 0 0"/>
    <limit effort="2.0" lower="-2" upper="2" velocity="0.001"/>
    <dynamics damping="0.02" friction="0.0"/>
    <origin rpy="0 0 0" xyz="0 0 0.0125"/>
    <parent link="RBseg8"/>
    <child link="RBseg9"/>
  </joint>
  <gazebo reference="RBseg8_RBseg9_joint">
    <implicitSpringDamper>True</implicitSpringDamper>
  </gazebo>
  <transmission name="RBseg8_RBseg9_trans">
    <type>transmission_interface/SimpleTransmission</type>
    <actuator name="RBseg8_RBseg9_motor">
      <mechanicalReduction>1</mechanicalReduction>
    </actuator>
    <joint name="RBseg8_RBseg9_joint">
      <hardwareInterface>hardware_interface/EffortJointInterface</hardwareInterface>
    </joint>
  </transmission>
  <gazebo reference="RBseg8_RBseg9_joint">
    <mu1 value="200.0"/>
    <mu2 value="100.0"/>
    <kp value="10000000.0"/>
    <kd value="1.0"/>
    <material>Gazebo/Grey</material>
  </gazebo>
  <link name="RBseg10">
    <visual>
      <geometry>
        <box size="0.0125 0.0125 0.0125"/>
      </geometry>
      <origin xyz="0 0 0"/>
      <material name="white"/>
    </visual>
    <inertial>
      <mass value="0.01"/>
      <origin rpy="0 0 0" xyz="0 0 0"/>
      <inertia ixx="2.604165625e-07" ixy="0.0" ixz="0.0" iyy="2.604165625e-07" iyz="0.0" izz="2.604165625e-07"/>
    </inertial>
    <!--
		<inertial>
			<mass value="0.001"/>
			<inertia ixx="0.000000001" ixy="0.000000001" ixz="0.000000001" iyy="0.000000001" iyz="0.000000001" izz="0.000000001"/>
		</inertial>
		-->
    <collision>
      <geometry>
        <box size="0.0125 0.0125 0.0125"/>
      </geometry>
      <origin xyz="0 0 0"/>
    </collision>
  </link>
  <gazebo reference="RBseg10">
    <!--plugin name='main_description' filename='libmain_description.so'/>-->
    <mu1>20000</mu1>
    <mu2>20000</mu2>
    <selfCollide>true</selfCollide>
    <gravity>true</gravity>
  </gazebo>
  <joint name="RBseg9_RBseg10_joint" type="revolute">
    <axis xyz="1 0 0"/>
    <limit effort="2.0" lower="-2" upper="2" velocity="0.001"/>
    <dynamics damping="0.02" friction="0.0"/>
    <origin rpy="0 0 0" xyz="0 0 0.0125"/>
    <parent link="RBseg9"/>
    <child link="RBseg10"/>
  </joint>
  <gazebo reference="RBseg9_RBseg10_joint">
    <implicitSpringDamper>True</implicitSpringDamper>
  </gazebo>
  <transmission name="RBseg9_RBseg10_trans">
    <type>transmission_interface/SimpleTransmission</type>
    <actuator name="RBseg9_RBseg10_motor">
      <mechanicalReduction>1</mechanicalReduction>
    </actuator>
    <joint name="RBseg9_RBseg10_joint">
      <hardwareInterface>hardware_interface/EffortJointInterface</hardwareInterface>
    </joint>
  </transmission>
  <gazebo reference="RBseg9_RBseg10_joint">
    <mu1 value="200.0"/>
    <mu2 value="100.0"/>
    <kp value="10000000.0"/>
    <kd value="1.0"/>
    <material>Gazebo/Grey</material>
  </gazebo>
  <link name="RBseg11">
    <visual>
      <geometry>
        <box size="0.0116666666667 0.0116666666667 0.0125"/>
      </geometry>
      <origin xyz="0 0 0"/>
      <material name="white"/>
    </visual>
    <inertial>
      <mass value="0.01"/>
      <origin rpy="0 0 0" xyz="0 0 0"/>
      <inertia ixx="2.43634161806e-07" ixy="0.0" ixz="0.0" iyy="2.43634161806e-07" iyz="0.0" izz="2.26851761112e-07"/>
    </inertial>
    <!--
		<inertial>
			<mass value="0.001"/>
			<inertia ixx="0.000000001" ixy="0.000000001" ixz="0.000000001" iyy="0.000000001" iyz="0.000000001" izz="0.000000001"/>
		</inertial>
		-->
    <collision>
      <geometry>
        <box size="0.0116666666667 0.0116666666667 0.0125"/>
      </geometry>
      <origin xyz="0 0 0"/>
    </collision>
  </link>
  <gazebo reference="RBseg11">
    <!--plugin name='main_description' filename='libmain_description.so'/>-->
    <mu1>20000</mu1>
    <mu2>20000</mu2>
    <selfCollide>true</selfCollide>
    <gravity>true</gravity>
  </gazebo>
  <joint name="RBseg10_RBseg11_joint" type="revolute">
    <axis xyz="1 0 0"/>
    <limit effort="2.0" lower="-2" upper="2" velocity="0.001"/>
    <dynamics damping="0.02" friction="0.0"/>
    <origin rpy="0 0 0" xyz="0 0 0.0125"/>
    <parent link="RBseg10"/>
    <child link="RBseg11"/>
  </joint>
  <gazebo reference="RBseg10_RBseg11_joint">
    <implicitSpringDamper>True</implicitSpringDamper>
  </gazebo>
  <transmission name="RBseg10_RBseg11_trans">
    <type>transmission_interface/SimpleTransmission</type>
    <actuator name="RBseg10_RBseg11_motor">
      <mechanicalReduction>1</mechanicalReduction>
    </actuator>
    <joint name="RBseg10_RBseg11_joint">
      <hardwareInterface>hardware_interface/EffortJointInterface</hardwareInterface>
    </joint>
  </transmission>
  <gazebo reference="RBseg10_RBseg11_joint">
    <mu1 value="200.0"/>
    <mu2 value="100.0"/>
    <kp value="10000000.0"/>
    <kd value="1.0"/>
    <material>Gazebo/Grey</material>
  </gazebo>
  <link name="RBseg12">
    <visual>
      <geometry>
        <box size="0.0108333333333 0.0108333333333 0.0125"/>
      </geometry>
      <origin xyz="0 0 0"/>
      <material name="white"/>
    </visual>
    <inertial>
      <mass value="0.01"/>
      <origin rpy="0 0 0" xyz="0 0 0"/>
      <inertia ixx="2.28009168055e-07" ixy="0.0" ixz="0.0" iyy="2.28009168055e-07" iyz="0.0" izz="1.9560177361e-07"/>
    </inertial>
    <!--
		<inertial>
			<mass value="0.001"/>
			<inertia ixx="0.000000001" ixy="0.000000001" ixz="0.000000001" iyy="0.000000001" iyz="0.000000001" izz="0.000000001"/>
		</inertial>
		-->
    <collision>
      <geometry>
        <box size="0.0108333333333 0.0108333333333 0.0125"/>
      </geometry>
      <origin xyz="0 0 0"/>
    </collision>
  </link>
  <gazebo reference="RBseg12">
    <!--plugin name='main_description' filename='libmain_description.so'/>-->
    <mu1>20000</mu1>
    <mu2>20000</mu2>
    <selfCollide>true</selfCollide>
    <gravity>true</gravity>
  </gazebo>
  <joint name="RBseg11_RBseg12_joint" type="revolute">
    <axis xyz="1 0 0"/>
    <limit effort="2.0" lower="-2" upper="2" velocity="0.001"/>
    <dynamics damping="0.02" friction="0.0"/>
    <origin rpy="0 0 0" xyz="0 0 0.0125"/>
    <parent link="RBseg11"/>
    <child link="RBseg12"/>
  </joint>
  <gazebo reference="RBseg11_RBseg12_joint">
    <implicitSpringDamper>True</implicitSpringDamper>
  </gazebo>
  <transmission name="RBseg11_RBseg12_trans">
    <type>transmission_interface/SimpleTransmission</type>
    <actuator name="RBseg11_RBseg12_motor">
      <mechanicalReduction>1</mechanicalReduction>
    </actuator>
    <joint name="RBseg11_RBseg12_joint">
      <hardwareInterface>hardware_interface/EffortJointInterface</hardwareInterface>
    </joint>
  </transmission>
  <gazebo reference="RBseg11_RBseg12_joint">
    <mu1 value="200.0"/>
    <mu2 value="100.0"/>
    <kp value="10000000.0"/>
    <kd value="1.0"/>
    <material>Gazebo/Grey</material>
  </gazebo>
</robot>

